Workbook

Sheet FAROL
B1: PROMOTORES
A2: 1 | B2: EVA LUNAS
A3: =A2+1 -> 2 | B3: CLEIVISON PEREIRA
A4: =A3+1 -> 3 | B4: JOSENILTON SOUZA
A5: =A4+1 -> 4 | B5: DANILO MENDONÇA
A6: =A5+1 -> 5 | B6: CLAUDINEI FERREIRA
A7: =A6+1 -> 6 | B7: GABRIEL SANTOS NEVES
A8: =A7+1 -> 7 | B8: HIRLAN ALVES
A9: =A8+1 -> 8 | B9: JOÃO VITOR FERREIRA
A10: =A9+1 -> 9 | B10: PAULO RICARDO

Sheet BASE DE CLIENTES
A1: Cli Cód | B1: Razão Social | C1: Fantasia | D1: Cidade | E1: Endereço | F1: Bairro | G1: Vd | H1: Sv | I1: Latitude | J1: Longitude | K1: LINK LOCALIZAÇÃO | L1: LOCALIZAÇÃO GPS | M1: TELEFONE | O1: NOME VD | P1: TELEFONE VD
A2: 0200-0004 | B2: ESTENE FREITAS CARMO | C2: CHURRASC PONTO CERTO | D2: IRECE | E2: AV PRIMEIRO DE JANEIRO, 31 | F2: CENTRO 3 | G2: 212 | H2: 200 | I2: -11.302038 | J2: -41.847767 | K2: ="https://www.google.com/maps?q="&""&LEFT(I2,3)&"."&RIGHT(I2,6)&", "&LEFT(J2,3)&"."&RIGHT(J2,6) -> https://www.google.com/maps?q=-11.302038, -41.847767 | L2: =HYPERLINK(K2,"Abrir no Maps") -> Abrir no Maps | M2: (400) 08821-1349 | O2: =VLOOKUP(G2,'[1]CONFIG.'!$B:$C,2,0) -> ANDRE | P2: =VLOOKUP(O2,'[1]CONFIG.'!$C:$D,2,0) -> 74 99916877
A3: 0200-0007 | B3: JOSE MARIA FERNANDES DE ALMEIDA | C3: REST E LANC ZE MARIA | D3: IRECE | E3: RUA JACINTO FIGUEREDO | F3: ANGICAL | G3: 211 | H3: 500 | I3: -11.240131 | J3: -41.755140 | K3: ="https://www.google.com/maps?q="&""&LEFT(I3,3)&"."&RIGHT(I3,6)&", "&LEFT(J3,3)&"."&RIGHT(J3,6) -> https://www.google.com/maps?q=-11.240131, -41.755140 | L3: =HYPERLINK(K3,"Abrir no Maps") -> Abrir no Maps | M3: (074) 99922-6072 | O3: =VLOOKUP(G3,'[1]CONFIG.'!$B:$C,2,0) -> DAIANE | P3: =VLOOKUP(O3,'[1]CONFIG.'!$C:$D,2,0) -> 74 99298866
A4: 0200-0019 | B4: DILTON PEREIRA COSTA | C4: CHURRASCARIA SAO FRA | D4: IRECE | E4: ROD BA 52 | F4: BA 052 | G4: 211 | H4: 500 | I4: -11.290277 | J4: -41.839720 | K4: ="https://www.google.com/maps?q="&""&LEFT(I4,3)&"."&RIGHT(I4,6)&", "&LEFT(J4,3)&"."&RIGHT(J4,6) -> https://www.google.com/maps?q=-11.290277, -41.839720 | L4: =HYPERLINK(K4,"Abrir no Maps") -> Abrir no Maps | M4: (074) 03641-9339 | O4: =VLOOKUP(G4,'[1]CONFIG.'!$B:$C,2,0) -> DAIANE | P4: =VLOOKUP(O4,'[1]CONFIG.'!$C:$D,2,0) -> 74 99298866
A5: 0200-0020 | B5: FRANCISCO AMITERLAN ANDRADE SI | C5: REST CHAPEU DE COURO | D5: IRECE | E5: AV SANTOS LOPES, 1660 | F5: SILVA PEREIRA | G5: 211 | H5: 500 | I5: -11.287683 | J5: -41.847990 | K5: ="https://www.google.com/maps?q="&""&LEFT(I5,3)&"."&RIGHT(I5,6)&", "&LEFT(J5,3)&"."&RIGHT(J5,6) -> https://www.google.com/maps?q=-11.287683, -41.847990 | L5: =HYPERLINK(K5,"Abrir no Maps") -> Abrir no Maps | M5: (400) 09965-6504 | O5: =VLOOKUP(G5,'[1]CONFIG.'!$B:$C,2,0) -> DAIANE | P5: =VLOOKUP(O5,'[1]CONFIG.'!$C:$D,2,0) -> 74 99298866
A6: 0200-0023 | B6: EDNA MAGNA DA SILVA | C6: LANCH CAFE COM LEITE | D6: IRECE | E6: RUA RODOVIA BA 052 KM | F6: BA 052 | G6: 211 | H6: 500 | I6: -11.290862 | J6: -41.839860 | K6: ="https://www.google.com/maps?q="&""&LEFT(I6,3)&"."&RIGHT(I6,6)&", "&LEFT(J6,3)&"."&RIGHT(J6,6) -> https://www.google.com/maps?q=-11.290862, -41.839860 | L6: =HYPERLINK(K6,"Abrir no Maps") -> Abrir no Maps | M6: (074) 99995-3842 | O6: =VLOOKUP(G6,'[1]CONFIG.'!$B:$C,2,0) -> DAIANE | P6: =VLOOKUP(O6,'[1]CONFIG.'!$C:$D,2,0) -> 74 99298866
A7: 0200-0024 | B7: FRANCISCA SALUSTIANA SANTOS | C7: MERCEARIA DA FRANCIS | D7: IRECE | E7: RUA PROF ILDA VASCONCELOS, 13 | F7: GINASIO DE ESPORTES | G7: 204 | H7: 500 | I7: -11.299548 | J7: -41.855328 | K7: ="https://www.google.com/maps?q="&""&LEFT(I7,3)&"."&RIGHT(I7,6)&", "&LEFT(J7,3)&"."&RIGHT(J7,6) -> https://www.google.com/maps?q=-11.299548, -41.855328 | L7: =HYPERLINK(K7,"Abrir no Maps") -> Abrir no Maps | M7: (740) 03641-3542 | O7: =VLOOKUP(G7,'[1]CONFIG.'!$B:$C,2,0) -> EVA | P7: =VLOOKUP(O7,'[1]CONFIG.'!$C:$D,2,0) -> 74 98046078
A8: 0200-0031 | B8: ZENAIDE BATISTA NOGUEIRA | C8: BAR E MERC NOGUEIRA | D8: IRECE | E8: PRC MARCIONILIO ROSA, 93 | F8: BOA VISTA | G8: 210 | H8: 500 | I8: -11.302778 | J8: -41.872500 | K8: ="https://www.google.com/maps?q="&""&LEFT(I8,3)&"."&RIGHT(I8,6)&", "&LEFT(J8,3)&"."&RIGHT(J8,6) -> https://www.google.com/maps?q=-11.302778, -41.872500 | L8: =HYPERLINK(K8,"Abrir no Maps") -> Abrir no Maps | M8: (740) 99972-2930 | O8: =VLOOKUP(G8,'[1]CONFIG.'!$B:$C,2,0) -> SILAS | P8: =VLOOKUP(O8,'[1]CONFIG.'!$C:$D,2,0) -> 74 98041875
A9: 0200-0048 | B9: ELIAS DOURADO RAMOS | C9: CHURRASCARIA PALADAR | D9: IRECE | E9: AV ADOLFO MOITINHO, 44 | F9: CENTRO 1 | G9: 209 | H9: 500 | I9: -11.303440 | J9: -41.854847 | K9: ="https://www.google.com/maps?q="&""&LEFT(I9,3)&"."&RIGHT(I9,6)&", "&LEFT(J9,3)&"."&RIGHT(J9,6) -> https://www.google.com/maps?q=-11.303440, -41.854847 | L9: =HYPERLINK(K9,"Abrir no Maps") -> Abrir no Maps | M9: (740) 99949-7179 | O9: =VLOOKUP(G9,'[1]CONFIG.'!$B:$C,2,0) -> IGOR | P9: =VLOOKUP(O9,'[1]CONFIG.'!$C:$D,2,0) -> 74 99590346
A10: 0200-0049 | B10: ARISMARIO NOGUEIRA DA SILVA | C10: O PONTO DO BADINGA | D10: IRECE | E10: AV ADOLFO MOITINHO, 472 | F10: CENTRO 1 | G10: 209 | H10: 500 | I10: -11.302867 | J10: -41.851612 | K10: ="https://www.google.com/maps?q="&""&LEFT(I10,3)&"."&RIGHT(I10,6)&", "&LEFT(J10,3)&"."&RIGHT(J10,6) -> https://www.google.com/maps?q=-11.302867, -41.851612 | L10: =HYPERLINK(K10,"Abrir no Maps") -> Abrir no Maps | M10: (074) 99995-9820 | O10: =VLOOKUP(G10,'[1]CONFIG.'!$B:$C,2,0) -> IGOR | P10: =VLOOKUP(O10,'[1]CONFIG.'!$C:$D,2,0) -> 74 99590346
A11: 0200-0056 | B11: EPITACIO ALVES ROCHA | C11: RESTAURANTE BOA VIAG | D11: IRECE | E11: AV AV RAIMUNDO BONFIM, 500 | F11: COOPIRECE | G11: 207 | H11: 500 | I11: -11.309420 | J11: -41.863262 | K11: ="https://www.google.com/maps?q="&""&LEFT(I11,3)&"."&RIGHT(I11,6)&", "&LEFT(J11,3)&"."&RIGHT(J11,6) -> https://www.google.com/maps?q=-11.309420, -41.863262 | L11: =HYPERLINK(K11,"Abrir no Maps") -> Abrir no Maps | M11: (074) 03641-4433 | O11: =VLOOKUP(G11,'[1]CONFIG.'!$B:$C,2,0) -> HIAGO | P11: =VLOOKUP(O11,'[1]CONFIG.'!$C:$D,2,0) -> 74 99872571
A12: 0200-0069 | B12: FRANCISCO BEZERRA DE ARAUJO | C12: MERCADINHO ARAUJO | D12: IRECE | E12: RUA ANTONIO OTAVIANO DOURADO, 475 | F12: CENTRO 3 | G12: 212 | H12: 200 | I12: -11.304084 | J12: -41.849476 | K12: ="https://www.google.com/maps?q="&""&LEFT(I12,3)&"."&RIGHT(I12,6)&", "&LEFT(J12,3)&"."&RIGHT(J12,6) -> https://www.google.com/maps?q=-11.304084, -41.849476 | L12: =HYPERLINK(K12,"Abrir no Maps") -> Abrir no Maps | M12: (074) 99957-8717 | O12: =VLOOKUP(G12,'[1]CONFIG.'!$B:$C,2,0) -> ANDRE | P12: =VLOOKUP(O12,'[1]CONFIG.'!$C:$D,2,0) -> 74 99916877
A13: 0200-0070 | B13: JENALDO SANTANA CARMO | C13: KIT LANCHES | D13: IRECE | E13: RUA ANTONIO OTAVIANO DOURADO, 414 | F13: CENTRO 3 | G13: 212 | H13: 200 | I13: -11.303965 | J13: -41.849860 | K13: ="https://www.google.com/maps?q="&""&LEFT(I13,3)&"."&RIGHT(I13,6)&", "&LEFT(J13,3)&"."&RIGHT(J13,6) -> https://www.google.com/maps?q=-11.303965, -41.849860 | L13: =HYPERLINK(K13,"Abrir no Maps") -> Abrir no Maps | M13: (074) 98846-2820 | O13: =VLOOKUP(G13,'[1]CONFIG.'!$B:$C,2,0) -> ANDRE | P13: =VLOOKUP(O13,'[1]CONFIG.'!$C:$D,2,0) -> 74 99916877
... A20: 0200-0153 | B20: EDILTON GOMES DOS SANTOS | C20: MERCADINHO GOMES0004 | D20: IRECE | E20: AV PROF JOEL LOPES, 754 | F20: CENTRO 4 | G20: 204 | H20: 500 | I20: -11.303382 | J20: -41.867477 | K20: ="https://www.google.com/maps?q="&""&LEFT(I20,3)&"."&RIGHT(I20,6)&", "&LEFT(J20,3)&"."&RIGHT(J20,6) -> https://www.google.com/maps?q=-11.303382, -41.867477 | L20: =HYPERLINK(K20,"Abrir no Maps") -> Abrir no Maps | M20: (740) 00641-1840 | O20: =VLOOKUP(G20,'[1]CONFIG.'!$B:$C,2,0) -> EVA | P20: =VLOOKUP(O20,'[1]CONFIG.'!$C:$D,2,0) -> 74 98046078
A21: 0200-0154 | B21: MIGUEL SILVA NUNES | C21: SUPERMINI L M | D21: IRECE | E21: RUA AV PROF JOEL LOPES, 1045 | F21: BOA VISTA | G21: 204 | H21: 500 | I21: -11.303427 | J21: -41.869873 | K21: ="https://www.google.com/maps?q="&""&LEFT(I21,3)&"."&RIGHT(I21,6)&", "&LEFT(J21,3)&"."&RIGHT(J21,6) -> https://www.google.com/maps?q=-11.303427, -41.869873 | L21: =HYPERLINK(K21,"Abrir no Maps") -> Abrir no Maps | M21: 0 | O21: =VLOOKUP(G21,'[1]CONFIG.'!$B:$C,2,0) -> EVA | P21: =VLOOKUP(O21,'[1]CONFIG.'!$C:$D,2,0) -> 74 98046078
A22: 0200-0159 | B22: MILTON TEIXEIRA BORGES | C22: MILTON TEIXEIRA BORG | D22: IRECE | E22: RUA JOSE ALVES DE ANDRADE, 516 | F22: CENTRO 3 | G22: 212 | H22: 200 | I22: -11.304659 | J22: -41.853455 | K22: ="https://www.google.com/maps?q="&""&LEFT(I22,3)&"."&RIGHT(I22,6)&", "&LEFT(J22,3)&"."&RIGHT(J22,6) -> https://www.google.com/maps?q=-11.304659, -41.853455 | L22: =HYPERLINK(K22,"Abrir no Maps") -> Abrir no Maps | M22: (740) 08803-2692 | O22: =VLOOKUP(G22,'[1]CONFIG.'!$B:$C,2,0) -> ANDRE | P22: =VLOOKUP(O22,'[1]CONFIG.'!$C:$D,2,0) -> 74 99916877
A23: 0200-0161 | B23: GILBERTO ALVES SANTOS SOBRINHO | C23: BONAMASSA PANIFICADO | D23: IRECE | E23: RUA LAFAIETE COUTINHO, 304 | F23: CENTRO | G23: 212 | H23: 200 | I23: -11.301513 | J23: -41.851340 | K23: ="https://www.google.com/maps?q="&""&LEFT(I23,3)&"."&RIGHT(I23,6)&", "&LEFT(J23,3)&"."&RIGHT(J23,6) -> https://www.google.com/maps?q=-11.301513, -41.851340 | L23: =HYPERLINK(K23,"Abrir no Maps") -> Abrir no Maps | M23: (074) 03641-9059 | O23: =VLOOKUP(G23,'[1]CONFIG.'!$B:$C,2,0) -> ANDRE | P23: =VLOOKUP(O23,'[1]CONFIG.'!$C:$D,2,0) -> 74 99916877
A24: 0200-0177 | B24: MARIA MADALENA S BARBOSA | C24: BOX 71 01 | D24: IRECE | E24: RUA MERCADAO BOX, 81 | F24: MERCADAO | G24: 210 | H24: 500 | I24: -11.300917 | J24: -41.861070 | K24: ="https://www.google.com/maps?q="&""&LEFT(I24,3)&"."&RIGHT(I24,6)&", "&LEFT(J24,3)&"."&RIGHT(J24,6) -> https://www.google.com/maps?q=-11.300917, -41.861070 | L24: =HYPERLINK(K24,"Abrir no Maps") -> Abrir no Maps | M24: (074) 99901-8895 | O24: =VLOOKUP(G24,'[1]CONFIG.'!$B:$C,2,0) -> SILAS | P24: =VLOOKUP(O24,'[1]CONFIG.'!$C:$D,2,0) -> 74 98041875
A25: 0200-0180 | B25: COOP CONS FUNC BB MICROREGIAO | C25: COOBRASIL | D25: IRECE | E25: RUA NOEL NUTLES, 300 | F25: CENTRO 3 | G25: 203 | H25: 200 | I25: -11.307996 | J25: -41.854060 | K25: ="https://www.google.com/maps?q="&""&LEFT(I25,3)&"."&RIGHT(I25,6)&", "&LEFT(J25,3)&"."&RIGHT(J25,6) -> https://www.google.com/maps?q=-11.307996, -41.854060 | L25: =HYPERLINK(K25,"Abrir no Maps") -> Abrir no Maps | M25: (074) 03641-4432 | O25: =VLOOKUP(G25,'[1]CONFIG.'!$B:$C,2,0) -> ALEXANDRE | P25: =VLOOKUP(O25,'[1]CONFIG.'!$C:$D,2,0) -> 74 99653478
A26: 0200-0184 | B26: DOURILEIA MARTINS DE JESUS | C26: RESTAURANTE AVENID01 | D26: IRECE | E26: AV DO 1 DE JANEIRO, 122 | F26: SAO JOSE | G26: 212 | H26: 200 | I26: -11.299657 | J26: -41.846250 | K26: ="https://www.google.com/maps?q="&""&LEFT(I26,3)&"."&RIGHT(I26,6)&", "&LEFT(J26,3)&"."&RIGHT(J26,6) -> https://www.google.com/maps?q=-11.299657, -41.846250 | L26: =HYPERLINK(K26,"Abrir no Maps") -> Abrir no Maps | M26: (074) 99932-9060 | O26: =VLOOKUP(G26,'[1]CONFIG.'!$B:$C,2,0) -> ANDRE | P26: =VLOOKUP(O26,'[1]CONFIG.'!$C:$D,2,0) -> 74 99916877
A27: 0200-0189 | B27: ANTONIO CARLOS MENDES DE CARVA | C27: BAR DO ARARA | D27: IRECE | E27: PRC TEODORO SAMPAIO, 63 | F27: CENTRO 3 | G27: 212 | H27: 200 | I27: -11.305055 | J27: -41.854940 | K27: ="https://www.google.com/maps?q="&""&LEFT(I27,3)&"."&RIGHT(I27,6)&", "&LEFT(J27,3)&"."&RIGHT(J27,6) -> https://www.google.com/maps?q=-11.305055, -41.854940 | L27: =HYPERLINK(K27,"Abrir no Maps") -> Abrir no Maps | M27: (074) 09991-9343 | O27: =VLOOKUP(G27,'[1]CONFIG.'!$B:$C,2,0) -> ANDRE | P27: =VLOOKUP(O27,'[1]CONFIG.'!$C:$D,2,0) -> 74 99916877
A28: 0200-0191 | B28: NILTON FERREIRA DE BRITO | C28: BAR E MERC MAINARA | D28: IRECE | E28: RUA POV MEIA HORA | F28: MEIA HORA | G28: 211 | H28: 500 | I28: -11.294723 | J28: -41.820280 | K28: ="https://www.google.com/maps?q="&""&LEFT(I28,3)&"."&RIGHT(I28,6)&", "&LEFT(J28,3)&"."&RIGHT(J28,6) -> https://www.google.com/maps?q=-11.294723, -41.820280 | L28: =HYPERLINK(K28,"Abrir no Maps") -> Abrir no Maps | M28: (074) 99973-1599 | O28: =VLOOKUP(G28,'[1]CONFIG.'!$B:$C,2,0) -> DAIANE | P28: =VLOOKUP(O28,'[1]CONFIG.'!$C:$D,2,0) -> 74 99298866
A29: 0200-0194 | B29: GENILDA OLIVEIRA FEITOSA | C29: BAR BEM BOLADA | D29: IRECE | E29: PRC PRACA TEODORO SAMPAIO, 51 | F29: CENTRO 3 | G29: 212 | H29: 200 | I29: -11.305274 | J29: -41.855206 | K29: ="https://www.google.com/maps?q="&""&LEFT(I29,3)&"."&RIGHT(I29,6)&", "&LEFT(J29,3)&"."&RIGHT(J29,6) -> https://www.google.com/maps?q=-11.305274, -41.855206 | L29: =HYPERLINK(K29,"Abrir no Maps") -> Abrir no Maps | M29: (074) 99972-2754 | O29: =VLOOKUP(G29,'[1]CONFIG.'!$B:$C,2,0) -> ANDRE | P29: =VLOOKUP(O29,'[1]CONFIG.'!$C:$D,2,0) -> 74 99916877
A30: 0200-0206 | B30: MARGARETE PROFETA DOS SANTOS | C30: LANCHONETE LIMA 01 | D30: IRECE | E30: TML RODOVIARIO BOX TRES, 3 | F30: CENTRO 1 | G30: 209 | H30: 500 | I30: -11.302689 | J30: -41.848410 | K30: ="https://www.google.com/maps?q="&""&LEFT(I30,3)&"."&RIGHT(I30,6)&", "&LEFT(J30,3)&"."&RIGHT(J30,6) -> https://www.google.com/maps?q=-11.302689, -41.848410 | L30: =HYPERLINK(K30,"Abrir no Maps") -> Abrir no Maps | M30: (074) 09984-6414 | O30: =VLOOKUP(G30,'[1]CONFIG.'!$B:$C,2,0) -> IGOR | P30: =VLOOKUP(O30,'[1]CONFIG.'!$C:$D,2,0) -> 74 99590346
A31: 0200-0228 | B31: EDIVALDO LUIZ FERREIRA | C31: PADARIA ZABETE | D31: IRECE | E31: AV PROF JOEL LOPES, 726 | F31: CENTRO 4 | G31: 210 | H31: 500 | I31: -11.303522 | J31: -41.867153 | K31: ="https://www.google.com/maps?q="&""&LEFT(I31,3)&"."&RIGHT(I31,6)&", "&LEFT(J31,3)&"."&RIGHT(J31,6) -> https://www.google.com/maps?q=-11.303522, -41.867153 | L31: =HYPERLINK(K31,"Abrir no Maps") -> Abrir no Maps | M31: (074) 99962-2773 | O31: =VLOOKUP(G31,'[1]CONFIG.'!$B:$C,2,0) -> SILAS | P31: =VLOOKUP(O31,'[1]CONFIG.'!$C:$D,2,0) -> 74 98041875
A32: 0200-0237 | B32: ARNOLDO GOMES DOS SANTOS | C32: NOSSO RESTAURANTE | D32: IBITITA | E32: RUA RUA LUIZ VIANA FILHO, 19 | F32: CENTRO | G32: 204 | H32: 500 | I32: -11.547598 | J32: -41.978516 | K32: ="https://www.google.com/maps?q="&""&LEFT(I32,3)&"."&RIGHT(I32,6)&", "&LEFT(J32,3)&"."&RIGHT(J32,6) -> https://www.google.com/maps?q=-11.547598, -41.978516 | L32: =HYPERLINK(K32,"Abrir no Maps") -> Abrir no Maps | M32: (074) 99802-1981 | O32: =VLOOKUP(G32,'[1]CONFIG.'!$B:$C,2,0) -> EVA | P32: =VLOOKUP(O32,'[1]CONFIG.'!$C:$D,2,0) -> 74 98046078
A33: 0200-0239 | B33: JAIR PIRES DE OLIVEIRA | C33: BAR JAIR | D33: IRECE | E33: PRC TEODORO SAMPAIO, 86 | F33: CENTRO 3 | G33: 212 | H33: 200 | I33: -11.305210 | J33: -41.855797 | K33: ="https://www.google.com/maps?q="&""&LEFT(I33,3)&"."&RIGHT(I33,6)&", "&LEFT(J33,3)&"."&RIGHT(J33,6) -> https://www.google.com/maps?q=-11.305210, -41.855797 | L33: =HYPERLINK(K33,"Abrir no Maps") -> Abrir no Maps | M33: (074) 03641-4850 | O33: =VLOOKUP(G33,'[1]CONFIG.'!$B:$C,2,0) -> ANDRE | P33: =VLOOKUP(O33,'[1]CONFIG.'!$C:$D,2,0) -> 74 99916877
... A48: 0200-0332 | B48: RAIMUNDA BARBOSA DA SILVA | C48: MERCADINHO DO RONALD | D48: IRECE | E48: RUA MANDACARU, 81 | F48: NOVO HORIZONTE | G48: 203 | H48: 200 | I48: -11.299807 | J48: -41.864513 | K48: ="https://www.google.com/maps?q="&""&LEFT(I48,3)&"."&RIGHT(I48,6)&", "&LEFT(J48,3)&"."&RIGHT(J48,6) -> https://www.google.com/maps?q=-11.299807, -41.864513 | L48: =HYPERLINK(K48,"Abrir no Maps") -> Abrir no Maps | M48: (740) 03641-0299 | O48: =VLOOKUP(G48,'[1]CONFIG.'!$B:$C,2,0) -> ALEXANDRE | P48: =VLOOKUP(O48,'[1]CONFIG.'!$C:$D,2,0) -> 74 99653478
A49: 0200-0340 | B49: ANTONIO CARLOS SEBASTIAO | C49: MERCEARIA SANTO ANTO | D49: IRECE | E49: RUA CAICARA, 141 | F49: NOVO HORIZONTE | G49: 210 | H49: 500 | I49: -11.299033 | J49: -41.866310 | K49: ="https://www.google.com/maps?q="&""&LEFT(I49,3)&"."&RIGHT(I49,6)&", "&LEFT(J49,3)&"."&RIGHT(J49,6) -> https://www.google.com/maps?q=-11.299033, -41.866310 | L49: =HYPERLINK(K49,"Abrir no Maps") -> Abrir no Maps | M49: 0 | O49: =VLOOKUP(G49,'[1]CONFIG.'!$B:$C,2,0) -> SILAS | P49: =VLOOKUP(O49,'[1]CONFIG.'!$C:$D,2,0) -> 74 98041875
A50: 0200-0355 | B50: IRANILTON SOUZA VIEIRA | C50: PADARIA PARAISO | D50: IRECE | E50: CAM 17 CASA | F50: PARAISO | G50: 211 | H50: 500 | I50: -11.311047 | J50: -41.874380 | K50: ="https://www.google.com/maps?q="&""&LEFT(I50,3)&"."&RIGHT(I50,6)&", "&LEFT(J50,3)&"."&RIGHT(J50,6) -> https://www.google.com/maps?q=-11.311047, -41.874380 | L50: =HYPERLINK(K50,"Abrir no Maps") -> Abrir no Maps | M50: 0 | O50: =VLOOKUP(G50,'[1]CONFIG.'!$B:$C,2,0) -> DAIANE | P50: =VLOOKUP(O50,'[1]CONFIG.'!$C:$D,2,0) -> 74 99298866
A51: 0200-0382 | B51: MARCIA ROCHA DE OLIVEIRA | C51: PORTAL CAFE | D51: IRECE | E51: RUA BENEDITO OLIVEIRA DIAS, 106 | F51: SAO JOSE | G51: 204 | H51: 500 | I51: -11.303946 | J51: -41.846405 | K51: ="https://www.google.com/maps?q="&""&LEFT(I51,3)&"."&RIGHT(I51,6)&", "&LEFT(J51,3)&"."&RIGHT(J51,6) -> https://www.google.com/maps?q=-11.303946, -41.846405 | L51: =HYPERLINK(K51,"Abrir no Maps") -> Abrir no Maps | M51: (074) 99959-0295 | O51: =VLOOKUP(G51,'[1]CONFIG.'!$B:$C,2,0) -> EVA | P51: =VLOOKUP(O51,'[1]CONFIG.'!$C:$D,2,0) -> 74 98046078
A52: 0200-0383 | B52: ROGERIO DE OLIVEIRA LIMA | C52: BAR DO ZUQUINHA 01 | D52: IRECE | E52: PRC JOAO XXIII, 208 | F52: CENTRO 2 | G52: 212 | H52: 200 | I52: -11.304233 | J52: -41.856094 | K52: ="https://www.google.com/maps?q="&""&LEFT(I52,3)&"."&RIGHT(I52,6)&", "&LEFT(J52,3)&"."&RIGHT(J52,6) -> https://www.google.com/maps?q=-11.304233, -41.856094 | L52: =HYPERLINK(K52,"Abrir no Maps") -> Abrir no Maps | M52: (740) 09998-6716 | O52: =VLOOKUP(G52,'[1]CONFIG.'!$B:$C,2,0) -> ANDRE | P52: =VLOOKUP(O52,'[1]CONFIG.'!$C:$D,2,0) -> 74 99916877
A53: 0200-0384 | B53: ILDONETE ABADES NUNES | C53: MERCADINHO NUNES 02 | D53: IRECE | E53: RUA SAO JORGE, 34 | F53: SAO JOSE | G53: 209 | H53: 500 | I53: -11.304170 | J53: -41.844860 | K53: ="https://www.google.com/maps?q="&""&LEFT(I53,3)&"."&RIGHT(I53,6)&", "&LEFT(J53,3)&"."&RIGHT(J53,6) -> https://www.google.com/maps?q=-11.304170, -41.844860 | L53: =HYPERLINK(K53,"Abrir no Maps") -> Abrir no Maps | M53: (074) 99909-5327 | O53: =VLOOKUP(G53,'[1]CONFIG.'!$B:$C,2,0) -> IGOR | P53: =VLOOKUP(O53,'[1]CONFIG.'!$C:$D,2,0) -> 74 99590346
A54: 0200-0417 | B54: ALCIONE BARROS MIRANDA SILVA | C54: SUPERMERCADO SILVA03 | D54: IRECE | E54: AV SANTOS LOPES, 1062 / 02000417 | F54: FORUM | G54: 203 | H54: 200 | I54: -11.293333 | J54: -41.851112 | K54: ="https://www.google.com/maps?q="&""&LEFT(I54,3)&"."&RIGHT(I54,6)&", "&LEFT(J54,3)&"."&RIGHT(J54,6) -> https://www.google.com/maps?q=-11.293333, -41.851112 | L54: =HYPERLINK(K54,"Abrir no Maps") -> Abrir no Maps | M54: (074) 99915-4829 | O54: =VLOOKUP(G54,'[1]CONFIG.'!$B:$C,2,0) -> ALEXANDRE | P54: =VLOOKUP(O54,'[1]CONFIG.'!$C:$D,2,0) -> 74 99653478
A55: 0200-0422 | B55: VILTON LUIZ ALVES BARRETO | C55: CESTAO DA ECONOMIA02 | D55: MORRO DO CHAPEU | E55: RUA AVENIDA SENHOR DOS PASSOS, 133 | F55: CAPELINHA | G55: 201 | H55: 300 | I55: -11.547222 | J55: -41.155556 | K55: ="https://www.google.com/maps?q="&""&LEFT(I55,3)&"."&RIGHT(I55,6)&", "&LEFT(J55,3)&"."&RIGHT(J55,6) -> https://www.google.com/maps?q=-11.547222, -41.155556 | L55: =HYPERLINK(K55,"Abrir no Maps") -> Abrir no Maps | M55: (074) 99807-4936 | O55: =VLOOKUP(G55,'[1]CONFIG.'!$B:$C,2,0) -> EDSON | P55: =VLOOKUP(O55,'[1]CONFIG.'!$C:$D,2,0) -> 74 99403278
A56: 0200-0425 | B56: ALBERTO GOMES MACHADO | C56: COMERCIAL DIA A DIA | D56: IRECE | E56: RUA DR ANGELO DOURADO, 602 | F56: CENTRO 4 | G56: 210 | H56: 500 | I56: -11.304628 | J56: -41.863010 | K56: ="https://www.google.com/maps?q="&""&LEFT(I56,3)&"."&RIGHT(I56,6)&", "&LEFT(J56,3)&"."&RIGHT(J56,6) -> https://www.google.com/maps?q=-11.304628, -41.863010 | L56: =HYPERLINK(K56,"Abrir no Maps") -> Abrir no Maps | M56: (074) 99959-6642 R.:. | O56: =VLOOKUP(G56,'[1]CONFIG.'!$B:$C,2,0) -> SILAS | P56: =VLOOKUP(O56,'[1]CONFIG.'!$C:$D,2,0) -> 74 98041875
A57: 0200-0436 | B57: GILMACI DE SOUZA ALMEIDA | C57: COMERCIAL BENICIO | D57: IRECE | E57: RUA FERNANDO MACHADO, 396 | F57: CENTRO 4 | G57: 210 | H57: 500 | I57: -11.305589 | J57: -41.866386 | K57: ="https://www.google.com/maps?q="&""&LEFT(I57,3)&"."&RIGHT(I57,6)&", "&LEFT(J57,3)&"."&RIGHT(J57,6) -> https://www.google.com/maps?q=-11.305589, -41.866386 | L57: =HYPERLINK(K57,"Abrir no Maps") -> Abrir no Maps | M57: (074) 03641-6110 | O57: =VLOOKUP(G57,'[1]CONFIG.'!$B:$C,2,0) -> SILAS | P57: =VLOOKUP(O57,'[1]CONFIG.'!$C:$D,2,0) -> 74 98041875
A58: 0200-0440 | B58: MARIA SILVANA RAMALHO | C58: POYNT BAR E RETAURAN | D58: IRECE | E58: AV SANTOS LOPES, 1100 | F58: CENTRO | G58: 212 | H58: 200 | I58: -11.292952 | J58: -41.850983 | K58: ="https://www.google.com/maps?q="&""&LEFT(I58,3)&"."&RIGHT(I58,6)&", "&LEFT(J58,3)&"."&RIGHT(J58,6) -> https://www.google.com/maps?q=-11.292952, -41.850983 | L58: =HYPERLINK(K58,"Abrir no Maps") -> Abrir no Maps | M58: (074) 99973-9623 | O58: =VLOOKUP(G58,'[1]CONFIG.'!$B:$C,2,0) -> ANDRE | P58: =VLOOKUP(O58,'[1]CONFIG.'!$C:$D,2,0) -> 74 99916877
A59: 0200-0442 | B59: NIVALDO CAVALCANTE DE MIRANDA | C59: MERCADINHO VISAO 01 | D59: IRECE | E59: RUA MALASIA, 86 | F59: SHAMPOO CHARME | G59: 203 | H59: 200 | I59: -11.296293 | J59: -41.859300 | K59: ="https://www.google.com/maps?q="&""&LEFT(I59,3)&"."&RIGHT(I59,6)&", "&LEFT(J59,3)&"."&RIGHT(J59,6) -> https://www.google.com/maps?q=-11.296293, -41.859300 | L59: =HYPERLINK(K59,"Abrir no Maps") -> Abrir no Maps | M59: (074) 99965-9587 | O59: =VLOOKUP(G59,'[1]CONFIG.'!$B:$C,2,0) -> ALEXANDRE | P59: =VLOOKUP(O59,'[1]CONFIG.'!$C:$D,2,0) -> 74 99653478
A60: 0200-0445 | B60: ERLANIA MENDES CAMINHA | C60: MERCADO LIMA | D60: IRECE | E60: RUA BENEDITO OLIVEIRA DIAS, 171 | F60: SAO JOSE | G60: 212 | H60: 200 | I60: -11.303841 | J60: -41.846844 | K60: ="https://www.google.com/maps?q="&""&LEFT(I60,3)&"."&RIGHT(I60,6)&", "&LEFT(J60,3)&"."&RIGHT(J60,6) -> https://www.google.com/maps?q=-11.303841, -41.846844 | L60: =HYPERLINK(K60,"Abrir no Maps") -> Abrir no Maps | M60: (740) 03641-4316 | O60: =VLOOKUP(G60,'[1]CONFIG.'!$B:$C,2,0) -> ANDRE | P60: =VLOOKUP(O60,'[1]CONFIG.'!$C:$D,2,0) -> 74 99916877
...

Sheet JOSENILTON SOUZA
B2: SEG | F2: TER | J2: QUA | N2: QUI | R2: SEX | V2: SÁB
B3: COD. | C3: CLIENTE | D3: EQUIPAMENTO | E3: ATIVIDADE | F3: COD. | G3: CLIENTE | H3: EQUIPAMENTO | I3: ATIVIDADE | J3: COD. | K3: CLIENTE | L3: EQUIPAMENTO | M3: ATIVIDADE | N3: COD. | O3: CLIENTE | P3: EQUIPAMENTO | Q3: ATIVIDADE | R3: COD. | S3: CLIENTE | T3: EQUIPAMENTO | U3: ATIVIDADE | V3: COD. | W3: CLIENTE | X3: EQUIPAMENTO | Y3: ATIVIDADE
B4: 0200-0180 | C4: =IFERROR(VLOOKUP(B4,'BASE DE CLIENTES'!$A:$C,3,0),"") -> COOBRASIL | D4: RACK E GELADEIRA PANELINHA | E4: LIMPEZA, VERIFICAR VALIDADES, E ABASTECIMENTO. | G4: =IFERROR(VLOOKUP(F4,'BASE DE CLIENTES'!$A:$C,3,0),"") | K4: =IFERROR(VLOOKUP(J4,'BASE DE CLIENTES'!$A:$C,3,0),"") | O4: =IFERROR(VLOOKUP(N4,'BASE DE CLIENTES'!$A:$C,3,0),"") | S4: =IFERROR(VLOOKUP(R4,'BASE DE CLIENTES'!$A:$C,3,0),"") | W4: =IFERROR(VLOOKUP(V4,'BASE DE CLIENTES'!$A:$C,3,0),"")
D5: PONTA DE GONDOLA ENTRADA DE LOJA | E5: LIMPEZA, VERIFICAR VALIDADES, E ABASTECIMENTO. | G5: =IFERROR(VLOOKUP(F5,'BASE DE CLIENTES'!$A:$C,3,0),"") | K5: =IFERROR(VLOOKUP(J5,'BASE DE CLIENTES'!$A:$C,3,0),"") | O5: =IFERROR(VLOOKUP(N5,'BASE DE CLIENTES'!$A:$C,3,0),"") | S5: =IFERROR(VLOOKUP(R5,'BASE DE CLIENTES'!$A:$C,3,0),"") | W5: =IFERROR(VLOOKUP(V5,'BASE DE CLIENTES'!$A:$C,3,0),"")
D6: GONDOLA - SETOR DE BEBIDAS | E6: MANTER OS 2 METROS DE GONDOLA | G6: =IFERROR(VLOOKUP(F6,'BASE DE CLIENTES'!$A:$C,3,0),"") | K6: =IFERROR(VLOOKUP(J6,'BASE DE CLIENTES'!$A:$C,3,0),"") | O6: =IFERROR(VLOOKUP(N6,'BASE DE CLIENTES'!$A:$C,3,0),"") | S6: =IFERROR(VLOOKUP(R6,'BASE DE CLIENTES'!$A:$C,3,0),"") | W6: =IFERROR(VLOOKUP(V6,'BASE DE CLIENTES'!$A:$C,3,0),"")
D7: GELADEIRA KO | E7: LIMPEZA, VERIFICAR VALIDADES, E ABASTECIMENTO. | G7: =IFERROR(VLOOKUP(F7,'BASE DE CLIENTES'!$A:$C,3,0),"") | K7: =IFERROR(VLOOKUP(J7,'BASE DE CLIENTES'!$A:$C,3,0),"") | O7: =IFERROR(VLOOKUP(N7,'BASE DE CLIENTES'!$A:$C,3,0),"") | S7: =IFERROR(VLOOKUP(R7,'BASE DE CLIENTES'!$A:$C,3,0),"") | W7: =IFERROR(VLOOKUP(V7,'BASE DE CLIENTES'!$A:$C,3,0),"")
D8: DUAS PORTAS DE GELOPAR | E8: LIMPEZA, VERIFICAR VALIDADES, E ABASTECIMENTO. | G8: =IFERROR(VLOOKUP(F8,'BASE DE CLIENTES'!$A:$C,3,0),"") | K8: =IFERROR(VLOOKUP(J8,'BASE DE CLIENTES'!$A:$C,3,0),"") | O8: =IFERROR(VLOOKUP(N8,'BASE DE CLIENTES'!$A:$C,3,0),"") | S8: =IFERROR(VLOOKUP(R8,'BASE DE CLIENTES'!$A:$C,3,0),"") | W8: =IFERROR(VLOOKUP(V8,'BASE DE CLIENTES'!$A:$C,3,0),"")
D9: CARONA SESSÃO DE BISCOITO | E9: CASO NÃO TER, CONQUISTAR ESPAÇO. | G9: =IFERROR(VLOOKUP(F9,'BASE DE CLIENTES'!$A:$C,3,0),"") | K9: =IFERROR(VLOOKUP(J9,'BASE DE CLIENTES'!$A:$C,3,0),"") | O9: =IFERROR(VLOOKUP(N9,'BASE DE CLIENTES'!$A:$C,3,0),"") | S9: =IFERROR(VLOOKUP(R9,'BASE DE CLIENTES'!$A:$C,3,0),"") | W9: =IFERROR(VLOOKUP(V9,'BASE DE CLIENTES'!$A:$C,3,0),"")
D10: GELADEIRA MONSTER | E10: LIMPEZA, VERIFICAR VALIDADES, E ABASTECIMENTO. | G10: =IFERROR(VLOOKUP(F10,'BASE DE CLIENTES'!$A:$C,3,0),"") | K10: =IFERROR(VLOOKUP(J10,'BASE DE CLIENTES'!$A:$C,3,0),"") | O10: =IFERROR(VLOOKUP(N10,'BASE DE CLIENTES'!$A:$C,3,0),"") | S10: =IFERROR(VLOOKUP(R10,'BASE DE CLIENTES'!$A:$C,3,0),"") | W10: =IFERROR(VLOOKUP(V10,'BASE DE CLIENTES'!$A:$C,3,0),"")
D11: PONTA DE GONDOLA E FRIGOBAR MONSTER | E11: LIMPEZA, VERIFICAR VALIDADES, E ABASTECIMENTO. | G11: =IFERROR(VLOOKUP(F11,'BASE DE CLIENTES'!$A:$C,3,0),"") | K11: =IFERROR(VLOOKUP(J11,'BASE DE CLIENTES'!$A:$C,3,0),"") | O11: =IFERROR(VLOOKUP(N11,'BASE DE CLIENTES'!$A:$C,3,0),"") | S11: =IFERROR(VLOOKUP(R11,'BASE DE CLIENTES'!$A:$C,3,0),"") | W11: =IFERROR(VLOOKUP(V11,'BASE DE CLIENTES'!$A:$C,3,0),"")
D12: PONTO EXTRA NO HORTI FRUTI | E12: CASO NÃO TER, CONQUISTAR ESPAÇO. | G12: =IFERROR(VLOOKUP(F12,'BASE DE CLIENTES'!$A:$C,3,0),"") | K12: =IFERROR(VLOOKUP(J12,'BASE DE CLIENTES'!$A:$C,3,0),"") | O12: =IFERROR(VLOOKUP(N12,'BASE DE CLIENTES'!$A:$C,3,0),"") | S12: =IFERROR(VLOOKUP(R12,'BASE DE CLIENTES'!$A:$C,3,0),"") | W12: =IFERROR(VLOOKUP(V12,'BASE DE CLIENTES'!$A:$C,3,0),"")
D13: RACK KO - ABASTECIMENTO PADARIA. | E13: LIMPEZA, VERIFICAR VALIDADES, E ABASTECIMENTO. | G13: =IFERROR(VLOOKUP(F13,'BASE DE CLIENTES'!$A:$C,3,0),"") | K13: =IFERROR(VLOOKUP(J13,'BASE DE CLIENTES'!$A:$C,3,0),"") | O13: =IFERROR(VLOOKUP(N13,'BASE DE CLIENTES'!$A:$C,3,0),"") | S13: =IFERROR(VLOOKUP(R13,'BASE DE CLIENTES'!$A:$C,3,0),"") | W13: =IFERROR(VLOOKUP(V13,'BASE DE CLIENTES'!$A:$C,3,0),"")
D14: GELADEIRA E GELOPAR LANCHONETE | E14: LIMPEZA, VERIFICAR VALIDADES, E ABASTECIMENTO. | G14: =IFERROR(VLOOKUP(F14,'BASE DE CLIENTES'!$A:$C,3,0),"") | K14: =IFERROR(VLOOKUP(J14,'BASE DE CLIENTES'!$A:$C,3,0),"") | O14: =IFERROR(VLOOKUP(N14,'BASE DE CLIENTES'!$A:$C,3,0),"") | S14: =IFERROR(VLOOKUP(R14,'BASE DE CLIENTES'!$A:$C,3,0),"") | W14: =IFERROR(VLOOKUP(V14,'BASE DE CLIENTES'!$A:$C,3,0),"")
D15: ESTOQUE DA LOJA | E15: LIMPEZA, VERIFICAR VALIDADES, E ABASTECIMENTO. | G15: =IFERROR(VLOOKUP(F15,'BASE DE CLIENTES'!$A:$C,3,0),"") | K15: =IFERROR(VLOOKUP(J15,'BASE DE CLIENTES'!$A:$C,3,0),"") | O15: =IFERROR(VLOOKUP(N15,'BASE DE CLIENTES'!$A:$C,3,0),"") | S15: =IFERROR(VLOOKUP(R15,'BASE DE CLIENTES'!$A:$C,3,0),"") | W15: =IFERROR(VLOOKUP(V15,'BASE DE CLIENTES'!$A:$C,3,0),"")
G16: =IFERROR(VLOOKUP(F16,'BASE DE CLIENTES'!$A:$C,3,0),"") | K16: =IFERROR(VLOOKUP(J16,'BASE DE CLIENTES'!$A:$C,3,0),"") | O16: =IFERROR(VLOOKUP(N16,'BASE DE CLIENTES'!$A:$C,3,0),"") | S16: =IFERROR(VLOOKUP(R16,'BASE DE CLIENTES'!$A:$C,3,0),"") | W16: =IFERROR(VLOOKUP(V16,'BASE DE CLIENTES'!$A:$C,3,0),"")
B17: 0200-2889 | C17: =IFERROR(VLOOKUP(B17,'BASE DE CLIENTES'!$A:$C,3,0),"") -> MERCADO DESTAK 03 | D17: GELADEIRA KO PONTA DELADA 2 PORTAS. | G17: =IFERROR(VLOOKUP(F17,'BASE DE CLIENTES'!$A:$C,3,0),"") | K17: =IFERROR(VLOOKUP(J17,'BASE DE CLIENTES'!$A:$C,3,0),"") | O17: =IFERROR(VLOOKUP(N17,'BASE DE CLIENTES'!$A:$C,3,0),"") | S17: =IFERROR(VLOOKUP(R17,'BASE DE CLIENTES'!$A:$C,3,0),"") | W17: =IFERROR(VLOOKUP(V17,'BASE DE CLIENTES'!$A:$C,3,0),"")
D18: GELADEIRA KO - RETORNAVEIS. | G18: =IFERROR(VLOOKUP(F18,'BASE DE CLIENTES'!$A:$C,3,0),"") | K18: =IFERROR(VLOOKUP(J18,'BASE DE CLIENTES'!$A:$C,3,0),"") | O18: =IFERROR(VLOOKUP(N18,'BASE DE CLIENTES'!$A:$C,3,0),"") | S18: =IFERROR(VLOOKUP(R18,'BASE DE CLIENTES'!$A:$C,3,0),"") | W18: =IFERROR(VLOOKUP(V18,'BASE DE CLIENTES'!$A:$C,3,0),"")
D19: GELOPAR DO CLIENTE. | G19: =IFERROR(VLOOKUP(F19,'BASE DE CLIENTES'!$A:$C,3,0),"") | K19: =IFERROR(VLOOKUP(J19,'BASE DE CLIENTES'!$A:$C,3,0),"") | O19: =IFERROR(VLOOKUP(N19,'BASE DE CLIENTES'!$A:$C,3,0),"") | S19: =IFERROR(VLOOKUP(R19,'BASE DE CLIENTES'!$A:$C,3,0),"") | W19: =IFERROR(VLOOKUP(V19,'BASE DE CLIENTES'!$A:$C,3,0),"")
D20: GELADEIRA KO - FASTLANE 4 PORTAS | G20: =IFERROR(VLOOKUP(F20,'BASE DE CLIENTES'!$A:$C,3,0),"") | K20: =IFERROR(VLOOKUP(J20,'BASE DE CLIENTES'!$A:$C,3,0),"") | O20: =IFERROR(VLOOKUP(N20,'BASE DE CLIENTES'!$A:$C,3,0),"") | S20: =IFERROR(VLOOKUP(R20,'BASE DE CLIENTES'!$A:$C,3,0),"") | W20: =IFERROR(VLOOKUP(V20,'BASE DE CLIENTES'!$A:$C,3,0),"")
D21: PONTA DE GONDOLA E FRIGOBAR MONSTER | G21: =IFERROR(VLOOKUP(F21,'BASE DE CLIENTES'!$A:$C,3,0),"") | K21: =IFERROR(VLOOKUP(J21,'BASE DE CLIENTES'!$A:$C,3,0),"") | O21: =IFERROR(VLOOKUP(N21,'BASE DE CLIENTES'!$A:$C,3,0),"") | S21: =IFERROR(VLOOKUP(R21,'BASE DE CLIENTES'!$A:$C,3,0),"") | W21: =IFERROR(VLOOKUP(V21,'BASE DE CLIENTES'!$A:$C,3,0),"")
D22: RACK MAIS ECONOMIA - RETORNAVEIS. | G22: =IFERROR(VLOOKUP(F22,'BASE DE CLIENTES'!$A:$C,3,0),"") | K22: =IFERROR(VLOOKUP(J22,'BASE DE CLIENTES'!$A:$C,3,0),"") | O22: =IFERROR(VLOOKUP(N22,'BASE DE CLIENTES'!$A:$C,3,0),"") | S22: =IFERROR(VLOOKUP(R22,'BASE DE CLIENTES'!$A:$C,3,0),"") | W22: =IFERROR(VLOOKUP(V22,'BASE DE CLIENTES'!$A:$C,3,0),"")
D23: RACK PONTA DE GONDOLA - HORTIFRUTI | G23: =IFERROR(VLOOKUP(F23,'BASE DE CLIENTES'!$A:$C,3,0),"") | K23: =IFERROR(VLOOKUP(J23,'BASE DE CLIENTES'!$A:$C,3,0),"") | O23: =IFERROR(VLOOKUP(N23,'BASE DE CLIENTES'!$A:$C,3,0),"") | S23: =IFERROR(VLOOKUP(R23,'BASE DE CLIENTES'!$A:$C,3,0),"") | W23: =IFERROR(VLOOKUP(V23,'BASE DE CLIENTES'!$A:$C,3,0),"")
D24: RACK MULTICATEGORIA - MERCEARIA SALGADA | G24: =IFERROR(VLOOKUP(F24,'BASE DE CLIENTES'!$A:$C,3,0),"") | K24: =IFERROR(VLOOKUP(J24,'BASE DE CLIENTES'!$A:$C,3,0),"") | O24: =IFERROR(VLOOKUP(N24,'BASE DE CLIENTES'!$A:$C,3,0),"") | S24: =IFERROR(VLOOKUP(R24,'BASE DE CLIENTES'!$A:$C,3,0),"") | W24: =IFERROR(VLOOKUP(V24,'BASE DE CLIENTES'!$A:$C,3,0),"")
D25: 2 GELADEIRAS KO AÇOUGUE. | G25: =IFERROR(VLOOKUP(F25,'BASE DE CLIENTES'!$A:$C,3,0),"") | K25: =IFERROR(VLOOKUP(J25,'BASE DE CLIENTES'!$A:$C,3,0),"") | O25: =IFERROR(VLOOKUP(N25,'BASE DE CLIENTES'!$A:$C,3,0),"") | S25: =IFERROR(VLOOKUP(R25,'BASE DE CLIENTES'!$A:$C,3,0),"") | W25: =IFERROR(VLOOKUP(V25,'BASE DE CLIENTES'!$A:$C,3,0),"")
D26: RACK HIDRATAÇÃO. | G26: =IFERROR(VLOOKUP(F26,'BASE DE CLIENTES'!$A:$C,3,0),"") | K26: =IFERROR(VLOOKUP(J26,'BASE DE CLIENTES'!$A:$C,3,0),"") | O26: =IFERROR(VLOOKUP(N26,'BASE DE CLIENTES'!$A:$C,3,0),"") | S26: =IFERROR(VLOOKUP(R26,'BASE DE CLIENTES'!$A:$C,3,0),"") | W26: =IFERROR(VLOOKUP(V26,'BASE DE CLIENTES'!$A:$C,3,0),"")
D27: RACK KAPO - SETOR DE BISCOITOS. | G27: =IFERROR(VLOOKUP(F27,'BASE DE CLIENTES'!$A:$C,3,0),"") | K27: =IFERROR(VLOOKUP(J27,'BASE DE CLIENTES'!$A:$C,3,0),"") | O27: =IFERROR(VLOOKUP(N27,'BASE DE CLIENTES'!$A:$C,3,0),"") | S27: =IFERROR(VLOOKUP(R27,'BASE DE CLIENTES'!$A:$C,3,0),"") | W27: =IFERROR(VLOOKUP(V27,'BASE DE CLIENTES'!$A:$C,3,0),"")
B28: 0200-2024 | C28: =IFERROR(VLOOKUP(B28,'BASE DE CLIENTES'!$A:$C,3,0),"") -> SERTAO FRANGO | D28: 2 GELADEIRAS K.O ENTRADA DA LOJA | G28: =IFERROR(VLOOKUP(F28,'BASE DE CLIENTES'!$A:$C,3,0),"") | K28: =IFERROR(VLOOKUP(J28,'BASE DE CLIENTES'!$A:$C,3,0),"") | O28: =IFERROR(VLOOKUP(N28,'BASE DE CLIENTES'!$A:$C,3,0),"") | S28: =IFERROR(VLOOKUP(R28,'BASE DE CLIENTES'!$A:$C,3,0),"") | W28: =IFERROR(VLOOKUP(V28,'BASE DE CLIENTES'!$A:$C,3,0),"")
C29: =IFERROR(VLOOKUP(B29,'BASE DE CLIENTES'!$A:$C,3,0),"") | G29: =IFERROR(VLOOKUP(F29,'BASE DE CLIENTES'!$A:$C,3,0),"") | K29: =IFERROR(VLOOKUP(J29,'BASE DE CLIENTES'!$A:$C,3,0),"") | O29: =IFERROR(VLOOKUP(N29,'BASE DE CLIENTES'!$A:$C,3,0),"") | S29: =IFERROR(VLOOKUP(R29,'BASE DE CLIENTES'!$A:$C,3,0),"") | W29: =IFERROR(VLOOKUP(V29,'BASE DE CLIENTES'!$A:$C,3,0),"")
C30: =IFERROR(VLOOKUP(B30,'BASE DE CLIENTES'!$A:$C,3,0),"") | G30: =IFERROR(VLOOKUP(F30,'BASE DE CLIENTES'!$A:$C,3,0),"") | K30: =IFERROR(VLOOKUP(J30,'BASE DE CLIENTES'!$A:$C,3,0),"") | O30: =IFERROR(VLOOKUP(N30,'BASE DE CLIENTES'!$A:$C,3,0),"") | S30: =IFERROR(VLOOKUP(R30,'BASE DE CLIENTES'!$A:$C,3,0),"") | W30: =IFERROR(VLOOKUP(V30,'BASE DE CLIENTES'!$A:$C,3,0),"")
C31: =IFERROR(VLOOKUP(B31,'BASE DE CLIENTES'!$A:$C,3,0),"") | G31: =IFERROR(VLOOKUP(F31,'BASE DE CLIENTES'!$A:$C,3,0),"") | K31: =IFERROR(VLOOKUP(J31,'BASE DE CLIENTES'!$A:$C,3,0),"") | O31: =IFERROR(VLOOKUP(N31,'BASE DE CLIENTES'!$A:$C,3,0),"") | S31: =IFERROR(VLOOKUP(R31,'BASE DE CLIENTES'!$A:$C,3,0),"") | W31: =IFERROR(VLOOKUP(V31,'BASE DE CLIENTES'!$A:$C,3,0),"")
C32: =IFERROR(VLOOKUP(B32,'BASE DE CLIENTES'!$A:$C,3,0),"") | G32: =IFERROR(VLOOKUP(F32,'BASE DE CLIENTES'!$A:$C,3,0),"") | K32: =IFERROR(VLOOKUP(J32,'BASE DE CLIENTES'!$A:$C,3,0),"") | O32: =IFERROR(VLOOKUP(N32,'BASE DE CLIENTES'!$A:$C,3,0),"") | S32: =IFERROR(VLOOKUP(R32,'BASE DE CLIENTES'!$A:$C,3,0),"") | W32: =IFERROR(VLOOKUP(V32,'BASE DE CLIENTES'!$A:$C,3,0),"")
C33: =IFERROR(VLOOKUP(B33,'BASE DE CLIENTES'!$A:$C,3,0),"") | G33: =IFERROR(VLOOKUP(F33,'BASE DE CLIENTES'!$A:$C,3,0),"") | K33: =IFERROR(VLOOKUP(J33,'BASE DE CLIENTES'!$A:$C,3,0),"") | O33: =IFERROR(VLOOKUP(N33,'BASE DE CLIENTES'!$A:$C,3,0),"") | S33: =IFERROR(VLOOKUP(R33,'BASE DE CLIENTES'!$A:$C,3,0),"") | W33: =IFERROR(VLOOKUP(V33,'BASE DE CLIENTES'!$A:$C,3,0),"")
C34: =IFERROR(VLOOKUP(B34,'BASE DE CLIENTES'!$A:$C,3,0),"") | G34: =IFERROR(VLOOKUP(F34,'BASE DE CLIENTES'!$A:$C,3,0),"") | K34: =IFERROR(VLOOKUP(J34,'BASE DE CLIENTES'!$A:$C,3,0),"") | O34: =IFERROR(VLOOKUP(N34,'BASE DE CLIENTES'!$A:$C,3,0),"") | S34: =IFERROR(VLOOKUP(R34,'BASE DE CLIENTES'!$A:$C,3,0),"") | W34: =IFERROR(VLOOKUP(V34,'BASE DE CLIENTES'!$A:$C,3,0),"")
C35: =IFERROR(VLOOKUP(B35,'BASE DE CLIENTES'!$A:$C,3,0),"") | G35: =IFERROR(VLOOKUP(F35,'BASE DE CLIENTES'!$A:$C,3,0),"") | K35: =IFERROR(VLOOKUP(J35,'BASE DE CLIENTES'!$A:$C,3,0),"") | O35: =IFERROR(VLOOKUP(N35,'BASE DE CLIENTES'!$A:$C,3,0),"") | S35: =IFERROR(VLOOKUP(R35,'BASE DE CLIENTES'!$A:$C,3,0),"") | W35: =IFERROR(VLOOKUP(V35,'BASE DE CLIENTES'!$A:$C,3,0),"")
C36: =IFERROR(VLOOKUP(B36,'BASE DE CLIENTES'!$A:$C,3,0),"") | G36: =IFERROR(VLOOKUP(F36,'BASE DE CLIENTES'!$A:$C,3,0),"") | K36: =IFERROR(VLOOKUP(J36,'BASE DE CLIENTES'!$A:$C,3,0),"") | O36: =IFERROR(VLOOKUP(N36,'BASE DE CLIENTES'!$A:$C,3,0),"") | S36: =IFERROR(VLOOKUP(R36,'BASE DE CLIENTES'!$A:$C,3,0),"") | W36: =IFERROR(VLOOKUP(V36,'BASE DE CLIENTES'!$A:$C,3,0),"")
C37: =IFERROR(VLOOKUP(B37,'BASE DE CLIENTES'!$A:$C,3,0),"") | G37: =IFERROR(VLOOKUP(F37,'BASE DE CLIENTES'!$A:$C,3,0),"") | K37: =IFERROR(VLOOKUP(J37,'BASE DE CLIENTES'!$A:$C,3,0),"") | O37: =IFERROR(VLOOKUP(N37,'BASE DE CLIENTES'!$A:$C,3,0),"") | S37: =IFERROR(VLOOKUP(R37,'BASE DE CLIENTES'!$A:$C,3,0),"") | W37: =IFERROR(VLOOKUP(V37,'BASE DE CLIENTES'!$A:$C,3,0),"")
C38: =IFERROR(VLOOKUP(B38,'BASE DE CLIENTES'!$A:$C,3,0),"") | G38: =IFERROR(VLOOKUP(F38,'BASE DE CLIENTES'!$A:$C,3,0),"") | K38: =IFERROR(VLOOKUP(J38,'BASE DE CLIENTES'!$A:$C,3,0),"") | O38: =IFERROR(VLOOKUP(N38,'BASE DE CLIENTES'!$A:$C,3,0),"") | S38: =IFERROR(VLOOKUP(R38,'BASE DE CLIENTES'!$A:$C,3,0),"") | W38: =IFERROR(VLOOKUP(V38,'BASE DE CLIENTES'!$A:$C,3,0),"")
C39: =IFERROR(VLOOKUP(B39,'BASE DE CLIENTES'!$A:$C,3,0),"") | G39: =IFERROR(VLOOKUP(F39,'BASE DE CLIENTES'!$A:$C,3,0),"") | K39: =IFERROR(VLOOKUP(J39,'BASE DE CLIENTES'!$A:$C,3,0),"") | O39: =IFERROR(VLOOKUP(N39,'BASE DE CLIENTES'!$A:$C,3,0),"") | S39: =IFERROR(VLOOKUP(R39,'BASE DE CLIENTES'!$A:$C,3,0),"") | W39: =IFERROR(VLOOKUP(V39,'BASE DE CLIENTES'!$A:$C,3,0),"")
C40: =IFERROR(VLOOKUP(B40,'BASE DE CLIENTES'!$A:$C,3,0),"") | G40: =IFERROR(VLOOKUP(F40,'BASE DE CLIENTES'!$A:$C,3,0),"") | K40: =IFERROR(VLOOKUP(J40,'BASE DE CLIENTES'!$A:$C,3,0),"") | O40: =IFERROR(VLOOKUP(N40,'BASE DE CLIENTES'!$A:$C,3,0),"") | S40: =IFERROR(VLOOKUP(R40,'BASE DE CLIENTES'!$A:$C,3,0),"") | W40: =IFERROR(VLOOKUP(V40,'BASE DE CLIENTES'!$A:$C,3,0),"")
... C100: =IFERROR(VLOOKUP(B100,'BASE DE CLIENTES'!$A:$C,3,0),"") | G100: =IFERROR(VLOOKUP(F100,'BASE DE CLIENTES'!$A:$C,3,0),"") | K100: =IFERROR(VLOOKUP(J100,'BASE DE CLIENTES'!$A:$C,3,0),"") | O100: =IFERROR(VLOOKUP(N100,'BASE DE CLIENTES'!$A:$C,3,0),"") | S100: =IFERROR(VLOOKUP(R100,'BASE DE CLIENTES'!$A:$C,3,0),"") | W100: =IFERROR(VLOOKUP(V100,'BASE DE CLIENTES'!$A:$C,3,0),"")

Sheet EVA LUNAS
B2: SEG | F2: TER | J2: QUA | N2: QUI | R2: SEX | V2: SÁB
B3: COD. | C3: CLIENTE | D3: EQUIPAMENTO | E3: ATIVIDADE | F3: COD. | G3: CLIENTE | H3: EQUIPAMENTO | I3: ATIVIDADE | J3: COD. | K3: CLIENTE | L3: EQUIPAMENTO | M3: ATIVIDADE | N3: COD. | O3: CLIENTE | P3: EQUIPAMENTO | Q3: ATIVIDADE | R3: COD. | S3: CLIENTE | T3: EQUIPAMENTO | U3: ATIVIDADE | V3: COD. | W3: CLIENTE | X3: EQUIPAMENTO | Y3: ATIVIDADE
C4: =IFERROR(VLOOKUP(B4,'BASE DE CLIENTES'!$A:$C,3,0),"") | G4: =IFERROR(VLOOKUP(F4,'BASE DE CLIENTES'!$A:$C,3,0),"") | K4: =IFERROR(VLOOKUP(J4,'BASE DE CLIENTES'!$A:$C,3,0),"") | O4: =IFERROR(VLOOKUP(N4,'BASE DE CLIENTES'!$A:$C,3,0),"") | S4: =IFERROR(VLOOKUP(R4,'BASE DE CLIENTES'!$A:$C,3,0),"") | W4: =IFERROR(VLOOKUP(V4,'BASE DE CLIENTES'!$A:$C,3,0),"")
C5: =IFERROR(VLOOKUP(B5,'BASE DE CLIENTES'!$A:$C,3,0),"") | G5: =IFERROR(VLOOKUP(F5,'BASE DE CLIENTES'!$A:$C,3,0),"") | K5: =IFERROR(VLOOKUP(J5,'BASE DE CLIENTES'!$A:$C,3,0),"") | O5: =IFERROR(VLOOKUP(N5,'BASE DE CLIENTES'!$A:$C,3,0),"") | S5: =IFERROR(VLOOKUP(R5,'BASE DE CLIENTES'!$A:$C,3,0),"") | W5: =IFERROR(VLOOKUP(V5,'BASE DE CLIENTES'!$A:$C,3,0),"")
C6: =IFERROR(VLOOKUP(B6,'BASE DE CLIENTES'!$A:$C,3,0),"") | G6: =IFERROR(VLOOKUP(F6,'BASE DE CLIENTES'!$A:$C,3,0),"") | K6: =IFERROR(VLOOKUP(J6,'BASE DE CLIENTES'!$A:$C,3,0),"") | O6: =IFERROR(VLOOKUP(N6,'BASE DE CLIENTES'!$A:$C,3,0),"") | S6: =IFERROR(VLOOKUP(R6,'BASE DE CLIENTES'!$A:$C,3,0),"") | W6: =IFERROR(VLOOKUP(V6,'BASE DE CLIENTES'!$A:$C,3,0),"")
C7: =IFERROR(VLOOKUP(B7,'BASE DE CLIENTES'!$A:$C,3,0),"") | G7: =IFERROR(VLOOKUP(F7,'BASE DE CLIENTES'!$A:$C,3,0),"") | K7: =IFERROR(VLOOKUP(J7,'BASE DE CLIENTES'!$A:$C,3,0),"") | O7: =IFERROR(VLOOKUP(N7,'BASE DE CLIENTES'!$A:$C,3,0),"") | S7: =IFERROR(VLOOKUP(R7,'BASE DE CLIENTES'!$A:$C,3,0),"") | W7: =IFERROR(VLOOKUP(V7,'BASE DE CLIENTES'!$A:$C,3,0),"")
C8: =IFERROR(VLOOKUP(B8,'BASE DE CLIENTES'!$A:$C,3,0),"") | G8: =IFERROR(VLOOKUP(F8,'BASE DE CLIENTES'!$A:$C,3,0),"") | K8: =IFERROR(VLOOKUP(J8,'BASE DE CLIENTES'!$A:$C,3,0),"") | O8: =IFERROR(VLOOKUP(N8,'BASE DE CLIENTES'!$A:$C,3,0),"") | S8: =IFERROR(VLOOKUP(R8,'BASE DE CLIENTES'!$A:$C,3,0),"") | W8: =IFERROR(VLOOKUP(V8,'BASE DE CLIENTES'!$A:$C,3,0),"")
C9: =IFERROR(VLOOKUP(B9,'BASE DE CLIENTES'!$A:$C,3,0),"") | G9: =IFERROR(VLOOKUP(F9,'BASE DE CLIENTES'!$A:$C,3,0),"") | K9: =IFERROR(VLOOKUP(J9,'BASE DE CLIENTES'!$A:$C,3,0),"") | O9: =IFERROR(VLOOKUP(N9,'BASE DE CLIENTES'!$A:$C,3,0),"") | S9: =IFERROR(VLOOKUP(R9,'BASE DE CLIENTES'!$A:$C,3,0),"") | W9: =IFERROR(VLOOKUP(V9,'BASE DE CLIENTES'!$A:$C,3,0),"")
C10: =IFERROR(VLOOKUP(B10,'BASE DE CLIENTES'!$A:$C,3,0),"") | G10: =IFERROR(VLOOKUP(F10,'BASE DE CLIENTES'!$A:$C,3,0),"") | K10: =IFERROR(VLOOKUP(J10,'BASE DE CLIENTES'!$A:$C,3,0),"") | O10: =IFERROR(VLOOKUP(N10,'BASE DE CLIENTES'!$A:$C,3,0),"") | S10: =IFERROR(VLOOKUP(R10,'BASE DE CLIENTES'!$A:$C,3,0),"") | W10: =IFERROR(VLOOKUP(V10,'BASE DE CLIENTES'!$A:$C,3,0),"")
C11: =IFERROR(VLOOKUP(B11,'BASE DE CLIENTES'!$A:$C,3,0),"") | G11: =IFERROR(VLOOKUP(F11,'BASE DE CLIENTES'!$A:$C,3,0),"") | K11: =IFERROR(VLOOKUP(J11,'BASE DE CLIENTES'!$A:$C,3,0),"") | O11: =IFERROR(VLOOKUP(N11,'BASE DE CLIENTES'!$A:$C,3,0),"") | S11: =IFERROR(VLOOKUP(R11,'BASE DE CLIENTES'!$A:$C,3,0),"") | W11: =IFERROR(VLOOKUP(V11,'BASE DE CLIENTES'!$A:$C,3,0),"")
C12: =IFERROR(VLOOKUP(B12,'BASE DE CLIENTES'!$A:$C,3,0),"") | G12: =IFERROR(VLOOKUP(F12,'BASE DE CLIENTES'!$A:$C,3,0),"") | K12: =IFERROR(VLOOKUP(J12,'BASE DE CLIENTES'!$A:$C,3,0),"") | O12: =IFERROR(VLOOKUP(N12,'BASE DE CLIENTES'!$A:$C,3,0),"") | S12: =IFERROR(VLOOKUP(R12,'BASE DE CLIENTES'!$A:$C,3,0),"") | W12: =IFERROR(VLOOKUP(V12,'BASE DE CLIENTES'!$A:$C,3,0),"")
C13: =IFERROR(VLOOKUP(B13,'BASE DE CLIENTES'!$A:$C,3,0),"") | G13: =IFERROR(VLOOKUP(F13,'BASE DE CLIENTES'!$A:$C,3,0),"") | K13: =IFERROR(VLOOKUP(J13,'BASE DE CLIENTES'!$A:$C,3,0),"") | O13: =IFERROR(VLOOKUP(N13,'BASE DE CLIENTES'!$A:$C,3,0),"") | S13: =IFERROR(VLOOKUP(R13,'BASE DE CLIENTES'!$A:$C,3,0),"") | W13: =IFERROR(VLOOKUP(V13,'BASE DE CLIENTES'!$A:$C,3,0),"")
C14: =IFERROR(VLOOKUP(B14,'BASE DE CLIENTES'!$A:$C,3,0),"") | G14: =IFERROR(VLOOKUP(F14,'BASE DE CLIENTES'!$A:$C,3,0),"") | K14: =IFERROR(VLOOKUP(J14,'BASE DE CLIENTES'!$A:$C,3,0),"") | O14: =IFERROR(VLOOKUP(N14,'BASE DE CLIENTES'!$A:$C,3,0),"") | S14: =IFERROR(VLOOKUP(R14,'BASE DE CLIENTES'!$A:$C,3,0),"") | W14: =IFERROR(VLOOKUP(V14,'BASE DE CLIENTES'!$A:$C,3,0),"")
C15: =IFERROR(VLOOKUP(B15,'BASE DE CLIENTES'!$A:$C,3,0),"") | G15: =IFERROR(VLOOKUP(F15,'BASE DE CLIENTES'!$A:$C,3,0),"") | K15: =IFERROR(VLOOKUP(J15,'BASE DE CLIENTES'!$A:$C,3,0),"") | O15: =IFERROR(VLOOKUP(N15,'BASE DE CLIENTES'!$A:$C,3,0),"") | S15: =IFERROR(VLOOKUP(R15,'BASE DE CLIENTES'!$A:$C,3,0),"") | W15: =IFERROR(VLOOKUP(V15,'BASE DE CLIENTES'!$A:$C,3,0),"")
... C100: =IFERROR(VLOOKUP(B100,'BASE DE CLIENTES'!$A:$C,3,0),"") | G100: =IFERROR(VLOOKUP(F100,'BASE DE CLIENTES'!$A:$C,3,0),"") | K100: =IFERROR(VLOOKUP(J100,'BASE DE CLIENTES'!$A:$C,3,0),"") | O100: =IFERROR(VLOOKUP(N100,'BASE DE CLIENTES'!$A:$C,3,0),"") | S100: =IFERROR(VLOOKUP(R100,'BASE DE CLIENTES'!$A:$C,3,0),"") | W100: =IFERROR(VLOOKUP(V100,'BASE DE CLIENTES'!$A:$C,3,0),"")

Sheet CLEIVISON PEREIRA
B2: SEG | F2: TER | J2: QUA | N2: QUI | R2: SEX | V2: SÁB
B3: COD. | C3: CLIENTE | D3: EQUIPAMENTO | E3: ATIVIDADE | F3: COD. | G3: CLIENTE | H3: EQUIPAMENTO | I3: ATIVIDADE | J3: COD. | K3: CLIENTE | L3: EQUIPAMENTO | M3: ATIVIDADE | N3: COD. | O3: CLIENTE | P3: EQUIPAMENTO | Q3: ATIVIDADE | R3: COD. | S3: CLIENTE | T3: EQUIPAMENTO | U3: ATIVIDADE | V3: COD. | W3: CLIENTE | X3: EQUIPAMENTO | Y3: ATIVIDADE
C4: =IFERROR(VLOOKUP(B4,'BASE DE CLIENTES'!$A:$C,3,0),"") | G4: =IFERROR(VLOOKUP(F4,'BASE DE CLIENTES'!$A:$C,3,0),"") | K4: =IFERROR(VLOOKUP(J4,'BASE DE CLIENTES'!$A:$C,3,0),"") | O4: =IFERROR(VLOOKUP(N4,'BASE DE CLIENTES'!$A:$C,3,0),"") | S4: =IFERROR(VLOOKUP(R4,'BASE DE CLIENTES'!$A:$C,3,0),"") | W4: =IFERROR(VLOOKUP(V4,'BASE DE CLIENTES'!$A:$C,3,0),"")
C5: =IFERROR(VLOOKUP(B5,'BASE DE CLIENTES'!$A:$C,3,0),"") | G5: =IFERROR(VLOOKUP(F5,'BASE DE CLIENTES'!$A:$C,3,0),"") | K5: =IFERROR(VLOOKUP(J5,'BASE DE CLIENTES'!$A:$C,3,0),"") | O5: =IFERROR(VLOOKUP(N5,'BASE DE CLIENTES'!$A:$C,3,0),"") | S5: =IFERROR(VLOOKUP(R5,'BASE DE CLIENTES'!$A:$C,3,0),"") | W5: =IFERROR(VLOOKUP(V5,'BASE DE CLIENTES'!$A:$C,3,0),"")
C6: =IFERROR(VLOOKUP(B6,'BASE DE CLIENTES'!$A:$C,3,0),"") | G6: =IFERROR(VLOOKUP(F6,'BASE DE CLIENTES'!$A:$C,3,0),"") | K6: =IFERROR(VLOOKUP(J6,'BASE DE CLIENTES'!$A:$C,3,0),"") | O6: =IFERROR(VLOOKUP(N6,'BASE DE CLIENTES'!$A:$C,3,0),"") | S6: =IFERROR(VLOOKUP(R6,'BASE DE CLIENTES'!$A:$C,3,0),"") | W6: =IFERROR(VLOOKUP(V6,'BASE DE CLIENTES'!$A:$C,3,0),"")
C7: =IFERROR(VLOOKUP(B7,'BASE DE CLIENTES'!$A:$C,3,0),"") | G7: =IFERROR(VLOOKUP(F7,'BASE DE CLIENTES'!$A:$C,3,0),"") | K7: =IFERROR(VLOOKUP(J7,'BASE DE CLIENTES'!$A:$C,3,0),"") | O7: =IFERROR(VLOOKUP(N7,'BASE DE CLIENTES'!$A:$C,3,0),"") | S7: =IFERROR(VLOOKUP(R7,'BASE DE CLIENTES'!$A:$C,3,0),"") | W7: =IFERROR(VLOOKUP(V7,'BASE DE CLIENTES'!$A:$C,3,0),"")
C8: =IFERROR(VLOOKUP(B8,'BASE DE CLIENTES'!$A:$C,3,0),"") | G8: =IFERROR(VLOOKUP(F8,'BASE DE CLIENTES'!$A:$C,3,0),"") | K8: =IFERROR(VLOOKUP(J8,'BASE DE CLIENTES'!$A:$C,3,0),"") | O8: =IFERROR(VLOOKUP(N8,'BASE DE CLIENTES'!$A:$C,3,0),"") | S8: =IFERROR(VLOOKUP(R8,'BASE DE CLIENTES'!$A:$C,3,0),"") | W8: =IFERROR(VLOOKUP(V8,'BASE DE CLIENTES'!$A:$C,3,0),"")
C9: =IFERROR(VLOOKUP(B9,'BASE DE CLIENTES'!$A:$C,3,0),"") | G9: =IFERROR(VLOOKUP(F9,'BASE DE CLIENTES'!$A:$C,3,0),"") | K9: =IFERROR(VLOOKUP(J9,'BASE DE CLIENTES'!$A:$C,3,0),"") | O9: =IFERROR(VLOOKUP(N9,'BASE DE CLIENTES'!$A:$C,3,0),"") | S9: =IFERROR(VLOOKUP(R9,'BASE DE CLIENTES'!$A:$C,3,0),"") | W9: =IFERROR(VLOOKUP(V9,'BASE DE CLIENTES'!$A:$C,3,0),"")
C10: =IFERROR(VLOOKUP(B10,'BASE DE CLIENTES'!$A:$C,3,0),"") | G10: =IFERROR(VLOOKUP(F10,'BASE DE CLIENTES'!$A:$C,3,0),"") | K10: =IFERROR(VLOOKUP(J10,'BASE DE CLIENTES'!$A:$C,3,0),"") | O10: =IFERROR(VLOOKUP(N10,'BASE DE CLIENTES'!$A:$C,3,0),"") | S10: =IFERROR(VLOOKUP(R10,'BASE DE CLIENTES'!$A:$C,3,0),"") | W10: =IFERROR(VLOOKUP(V10,'BASE DE CLIENTES'!$A:$C,3,0),"")
C11: =IFERROR(VLOOKUP(B11,'BASE DE CLIENTES'!$A:$C,3,0),"") | G11: =IFERROR(VLOOKUP(F11,'BASE DE CLIENTES'!$A:$C,3,0),"") | K11: =IFERROR(VLOOKUP(J11,'BASE DE CLIENTES'!$A:$C,3,0),"") | O11: =IFERROR(VLOOKUP(N11,'BASE DE CLIENTES'!$A:$C,3,0),"") | S11: =IFERROR(VLOOKUP(R11,'BASE DE CLIENTES'!$A:$C,3,0),"") | W11: =IFERROR(VLOOKUP(V11,'BASE DE CLIENTES'!$A:$C,3,0),"")
C12: =IFERROR(VLOOKUP(B12,'BASE DE CLIENTES'!$A:$C,3,0),"") | G12: =IFERROR(VLOOKUP(F12,'BASE DE CLIENTES'!$A:$C,3,0),"") | K12: =IFERROR(VLOOKUP(J12,'BASE DE CLIENTES'!$A:$C,3,0),"") | O12: =IFERROR(VLOOKUP(N12,'BASE DE CLIENTES'!$A:$C,3,0),"") | S12: =IFERROR(VLOOKUP(R12,'BASE DE CLIENTES'!$A:$C,3,0),"") | W12: =IFERROR(VLOOKUP(V12,'BASE DE CLIENTES'!$A:$C,3,0),"")
C13: =IFERROR(VLOOKUP(B13,'BASE DE CLIENTES'!$A:$C,3,0),"") | G13: =IFERROR(VLOOKUP(F13,'BASE DE CLIENTES'!$A:$C,3,0),"") | K13: =IFERROR(VLOOKUP(J13,'BASE DE CLIENTES'!$A:$C,3,0),"") | O13: =IFERROR(VLOOKUP(N13,'BASE DE CLIENTES'!$A:$C,3,0),"") | S13: =IFERROR(VLOOKUP(R13,'BASE DE CLIENTES'!$A:$C,3,0),"") | W13: =IFERROR(VLOOKUP(V13,'BASE DE CLIENTES'!$A:$C,3,0),"")
C14: =IFERROR(VLOOKUP(B14,'BASE DE CLIENTES'!$A:$C,3,0),"") | G14: =IFERROR(VLOOKUP(F14,'BASE DE CLIENTES'!$A:$C,3,0),"") | K14: =IFERROR(VLOOKUP(J14,'BASE DE CLIENTES'!$A:$C,3,0),"") | O14: =IFERROR(VLOOKUP(N14,'BASE DE CLIENTES'!$A:$C,3,0),"") | S14: =IFERROR(VLOOKUP(R14,'BASE DE CLIENTES'!$A:$C,3,0),"") | W14: =IFERROR(VLOOKUP(V14,'BASE DE CLIENTES'!$A:$C,3,0),"")
C15: =IFERROR(VLOOKUP(B15,'BASE DE CLIENTES'!$A:$C,3,0),"") | G15: =IFERROR(VLOOKUP(F15,'BASE DE CLIENTES'!$A:$C,3,0),"") | K15: =IFERROR(VLOOKUP(J15,'BASE DE CLIENTES'!$A:$C,3,0),"") | O15: =IFERROR(VLOOKUP(N15,'BASE DE CLIENTES'!$A:$C,3,0),"") | S15: =IFERROR(VLOOKUP(R15,'BASE DE CLIENTES'!$A:$C,3,0),"") | W15: =IFERROR(VLOOKUP(V15,'BASE DE CLIENTES'!$A:$C,3,0),"")
... C100: =IFERROR(VLOOKUP(B100,'BASE DE CLIENTES'!$A:$C,3,0),"") | G100: =IFERROR(VLOOKUP(F100,'BASE DE CLIENTES'!$A:$C,3,0),"") | K100: =IFERROR(VLOOKUP(J100,'BASE DE CLIENTES'!$A:$C,3,0),"") | O100: =IFERROR(VLOOKUP(N100,'BASE DE CLIENTES'!$A:$C,3,0),"") | S100: =IFERROR(VLOOKUP(R100,'BASE DE CLIENTES'!$A:$C,3,0),"") | W100: =IFERROR(VLOOKUP(V100,'BASE DE CLIENTES'!$A:$C,3,0),"")

Sheet DANILO MENDONÇA
B2: SEG | F2: TER | J2: QUA | N2: QUI | R2: SEX | V2: SÁB
B3: COD. | C3: CLIENTE | D3: EQUIPAMENTO | E3: ATIVIDADE | F3: COD. | G3: CLIENTE | H3: EQUIPAMENTO | I3: ATIVIDADE | J3: COD. | K3: CLIENTE | L3: EQUIPAMENTO | M3: ATIVIDADE | N3: COD. | O3: CLIENTE | P3: EQUIPAMENTO | Q3: ATIVIDADE | R3: COD. | S3: CLIENTE | T3: EQUIPAMENTO | U3: ATIVIDADE | V3: COD. | W3: CLIENTE | X3: EQUIPAMENTO | Y3: ATIVIDADE
C4: =IFERROR(VLOOKUP(B4,'BASE DE CLIENTES'!$A:$C,3,0),"") | G4: =IFERROR(VLOOKUP(F4,'BASE DE CLIENTES'!$A:$C,3,0),"") | K4: =IFERROR(VLOOKUP(J4,'BASE DE CLIENTES'!$A:$C,3,0),"") | O4: =IFERROR(VLOOKUP(N4,'BASE DE CLIENTES'!$A:$C,3,0),"") | S4: =IFERROR(VLOOKUP(R4,'BASE DE CLIENTES'!$A:$C,3,0),"") | W4: =IFERROR(VLOOKUP(V4,'BASE DE CLIENTES'!$A:$C,3,0),"")
C5: =IFERROR(VLOOKUP(B5,'BASE DE CLIENTES'!$A:$C,3,0),"") | G5: =IFERROR(VLOOKUP(F5,'BASE DE CLIENTES'!$A:$C,3,0),"") | K5: =IFERROR(VLOOKUP(J5,'BASE DE CLIENTES'!$A:$C,3,0),"") | O5: =IFERROR(VLOOKUP(N5,'BASE DE CLIENTES'!$A:$C,3,0),"") | S5: =IFERROR(VLOOKUP(R5,'BASE DE CLIENTES'!$A:$C,3,0),"") | W5: =IFERROR(VLOOKUP(V5,'BASE DE CLIENTES'!$A:$C,3,0),"")
C6: =IFERROR(VLOOKUP(B6,'BASE DE CLIENTES'!$A:$C,3,0),"") | G6: =IFERROR(VLOOKUP(F6,'BASE DE CLIENTES'!$A:$C,3,0),"") | K6: =IFERROR(VLOOKUP(J6,'BASE DE CLIENTES'!$A:$C,3,0),"") | O6: =IFERROR(VLOOKUP(N6,'BASE DE CLIENTES'!$A:$C,3,0),"") | S6: =IFERROR(VLOOKUP(R6,'BASE DE CLIENTES'!$A:$C,3,0),"") | W6: =IFERROR(VLOOKUP(V6,'BASE DE CLIENTES'!$A:$C,3,0),"")
C7: =IFERROR(VLOOKUP(B7,'BASE DE CLIENTES'!$A:$C,3,0),"") | G7: =IFERROR(VLOOKUP(F7,'BASE DE CLIENTES'!$A:$C,3,0),"") | K7: =IFERROR(VLOOKUP(J7,'BASE DE CLIENTES'!$A:$C,3,0),"") | O7: =IFERROR(VLOOKUP(N7,'BASE DE CLIENTES'!$A:$C,3,0),"") | S7: =IFERROR(VLOOKUP(R7,'BASE DE CLIENTES'!$A:$C,3,0),"") | W7: =IFERROR(VLOOKUP(V7,'BASE DE CLIENTES'!$A:$C,3,0),"")
C8: =IFERROR(VLOOKUP(B8,'BASE DE CLIENTES'!$A:$C,3,0),"") | G8: =IFERROR(VLOOKUP(F8,'BASE DE CLIENTES'!$A:$C,3,0),"") | K8: =IFERROR(VLOOKUP(J8,'BASE DE CLIENTES'!$A:$C,3,0),"") | O8: =IFERROR(VLOOKUP(N8,'BASE DE CLIENTES'!$A:$C,3,0),"") | S8: =IFERROR(VLOOKUP(R8,'BASE DE CLIENTES'!$A:$C,3,0),"") | W8: =IFERROR(VLOOKUP(V8,'BASE DE CLIENTES'!$A:$C,3,0),"")
C9: =IFERROR(VLOOKUP(B9,'BASE DE CLIENTES'!$A:$C,3,0),"") | G9: =IFERROR(VLOOKUP(F9,'BASE DE CLIENTES'!$A:$C,3,0),"") | K9: =IFERROR(VLOOKUP(J9,'BASE DE CLIENTES'!$A:$C,3,0),"") | O9: =IFERROR(VLOOKUP(N9,'BASE DE CLIENTES'!$A:$C,3,0),"") | S9: =IFERROR(VLOOKUP(R9,'BASE DE CLIENTES'!$A:$C,3,0),"") | W9: =IFERROR(VLOOKUP(V9,'BASE DE CLIENTES'!$A:$C,3,0),"")
C10: =IFERROR(VLOOKUP(B10,'BASE DE CLIENTES'!$A:$C,3,0),"") | G10: =IFERROR(VLOOKUP(F10,'BASE DE CLIENTES'!$A:$C,3,0),"") | K10: =IFERROR(VLOOKUP(J10,'BASE DE CLIENTES'!$A:$C,3,0),"") | O10: =IFERROR(VLOOKUP(N10,'BASE DE CLIENTES'!$A:$C,3,0),"") | S10: =IFERROR(VLOOKUP(R10,'BASE DE CLIENTES'!$A:$C,3,0),"") | W10: =IFERROR(VLOOKUP(V10,'BASE DE CLIENTES'!$A:$C,3,0),"")
C11: =IFERROR(VLOOKUP(B11,'BASE DE CLIENTES'!$A:$C,3,0),"") | G11: =IFERROR(VLOOKUP(F11,'BASE DE CLIENTES'!$A:$C,3,0),"") | K11: =IFERROR(VLOOKUP(J11,'BASE DE CLIENTES'!$A:$C,3,0),"") | O11: =IFERROR(VLOOKUP(N11,'BASE DE CLIENTES'!$A:$C,3,0),"") | S11: =IFERROR(VLOOKUP(R11,'BASE DE CLIENTES'!$A:$C,3,0),"") | W11: =IFERROR(VLOOKUP(V11,'BASE DE CLIENTES'!$A:$C,3,0),"")
C12: =IFERROR(VLOOKUP(B12,'BASE DE CLIENTES'!$A:$C,3,0),"") | G12: =IFERROR(VLOOKUP(F12,'BASE DE CLIENTES'!$A:$C,3,0),"") | K12: =IFERROR(VLOOKUP(J12,'BASE DE CLIENTES'!$A:$C,3,0),"") | O12: =IFERROR(VLOOKUP(N12,'BASE DE CLIENTES'!$A:$C,3,0),"") | S12: =IFERROR(VLOOKUP(R12,'BASE DE CLIENTES'!$A:$C,3,0),"") | W12: =IFERROR(VLOOKUP(V12,'BASE DE CLIENTES'!$A:$C,3,0),"")
C13: =IFERROR(VLOOKUP(B13,'BASE DE CLIENTES'!$A:$C,3,0),"") | G13: =IFERROR(VLOOKUP(F13,'BASE DE CLIENTES'!$A:$C,3,0),"") | K13: =IFERROR(VLOOKUP(J13,'BASE DE CLIENTES'!$A:$C,3,0),"") | O13: =IFERROR(VLOOKUP(N13,'BASE DE CLIENTES'!$A:$C,3,0),"") | S13: =IFERROR(VLOOKUP(R13,'BASE DE CLIENTES'!$A:$C,3,0),"") | W13: =IFERROR(VLOOKUP(V13,'BASE DE CLIENTES'!$A:$C,3,0),"")
C14: =IFERROR(VLOOKUP(B14,'BASE DE CLIENTES'!$A:$C,3,0),"") | G14: =IFERROR(VLOOKUP(F14,'BASE DE CLIENTES'!$A:$C,3,0),"") | K14: =IFERROR(VLOOKUP(J14,'BASE DE CLIENTES'!$A:$C,3,0),"") | O14: =IFERROR(VLOOKUP(N14,'BASE DE CLIENTES'!$A:$C,3,0),"") | S14: =IFERROR(VLOOKUP(R14,'BASE DE CLIENTES'!$A:$C,3,0),"") | W14: =IFERROR(VLOOKUP(V14,'BASE DE CLIENTES'!$A:$C,3,0),"")
C15: =IFERROR(VLOOKUP(B15,'BASE DE CLIENTES'!$A:$C,3,0),"") | G15: =IFERROR(VLOOKUP(F15,'BASE DE CLIENTES'!$A:$C,3,0),"") | K15: =IFERROR(VLOOKUP(J15,'BASE DE CLIENTES'!$A:$C,3,0),"") | O15: =IFERROR(VLOOKUP(N15,'BASE DE CLIENTES'!$A:$C,3,0),"") | S15: =IFERROR(VLOOKUP(R15,'BASE DE CLIENTES'!$A:$C,3,0),"") | W15: =IFERROR(VLOOKUP(V15,'BASE DE CLIENTES'!$A:$C,3,0),"")
... C100: =IFERROR(VLOOKUP(B100,'BASE DE CLIENTES'!$A:$C,3,0),"") | G100: =IFERROR(VLOOKUP(F100,'BASE DE CLIENTES'!$A:$C,3,0),"") | K100: =IFERROR(VLOOKUP(J100,'BASE DE CLIENTES'!$A:$C,3,0),"") | O100: =IFERROR(VLOOKUP(N100,'BASE DE CLIENTES'!$A:$C,3,0),"") | S100: =IFERROR(VLOOKUP(R100,'BASE DE CLIENTES'!$A:$C,3,0),"") | W100: =IFERROR(VLOOKUP(V100,'BASE DE CLIENTES'!$A:$C,3,0),"")

Sheet CLAUDINEI FERREIRA
B2: SEG | F2: TER | J2: QUA | N2: QUI | R2: SEX | V2: SÁB
B3: COD. | C3: CLIENTE | D3: EQUIPAMENTO | E3: ATIVIDADE | F3: COD. | G3: CLIENTE | H3: EQUIPAMENTO | I3: ATIVIDADE | J3: COD. | K3: CLIENTE | L3: EQUIPAMENTO | M3: ATIVIDADE | N3: COD. | O3: CLIENTE | P3: EQUIPAMENTO | Q3: ATIVIDADE | R3: COD. | S3: CLIENTE | T3: EQUIPAMENTO | U3: ATIVIDADE | V3: COD. | W3: CLIENTE | X3: EQUIPAMENTO | Y3: ATIVIDADE
C4: =IFERROR(VLOOKUP(B4,'BASE DE CLIENTES'!$A:$C,3,0),"") | G4: =IFERROR(VLOOKUP(F4,'BASE DE CLIENTES'!$A:$C,3,0),"") | K4: =IFERROR(VLOOKUP(J4,'BASE DE CLIENTES'!$A:$C,3,0),"") | O4: =IFERROR(VLOOKUP(N4,'BASE DE CLIENTES'!$A:$C,3,0),"") | S4: =IFERROR(VLOOKUP(R4,'BASE DE CLIENTES'!$A:$C,3,0),"") | W4: =IFERROR(VLOOKUP(V4,'BASE DE CLIENTES'!$A:$C,3,0),"")
C5: =IFERROR(VLOOKUP(B5,'BASE DE CLIENTES'!$A:$C,3,0),"") | G5: =IFERROR(VLOOKUP(F5,'BASE DE CLIENTES'!$A:$C,3,0),"") | K5: =IFERROR(VLOOKUP(J5,'BASE DE CLIENTES'!$A:$C,3,0),"") | O5: =IFERROR(VLOOKUP(N5,'BASE DE CLIENTES'!$A:$C,3,0),"") | S5: =IFERROR(VLOOKUP(R5,'BASE DE CLIENTES'!$A:$C,3,0),"") | W5: =IFERROR(VLOOKUP(V5,'BASE DE CLIENTES'!$A:$C,3,0),"")
C6: =IFERROR(VLOOKUP(B6,'BASE DE CLIENTES'!$A:$C,3,0),"") | G6: =IFERROR(VLOOKUP(F6,'BASE DE CLIENTES'!$A:$C,3,0),"") | K6: =IFERROR(VLOOKUP(J6,'BASE DE CLIENTES'!$A:$C,3,0),"") | O6: =IFERROR(VLOOKUP(N6,'BASE DE CLIENTES'!$A:$C,3,0),"") | S6: =IFERROR(VLOOKUP(R6,'BASE DE CLIENTES'!$A:$C,3,0),"") | W6: =IFERROR(VLOOKUP(V6,'BASE DE CLIENTES'!$A:$C,3,0),"")
C7: =IFERROR(VLOOKUP(B7,'BASE DE CLIENTES'!$A:$C,3,0),"") | G7: =IFERROR(VLOOKUP(F7,'BASE DE CLIENTES'!$A:$C,3,0),"") | K7: =IFERROR(VLOOKUP(J7,'BASE DE CLIENTES'!$A:$C,3,0),"") | O7: =IFERROR(VLOOKUP(N7,'BASE DE CLIENTES'!$A:$C,3,0),"") | S7: =IFERROR(VLOOKUP(R7,'BASE DE CLIENTES'!$A:$C,3,0),"") | W7: =IFERROR(VLOOKUP(V7,'BASE DE CLIENTES'!$A:$C,3,0),"")
C8: =IFERROR(VLOOKUP(B8,'BASE DE CLIENTES'!$A:$C,3,0),"") | G8: =IFERROR(VLOOKUP(F8,'BASE DE CLIENTES'!$A:$C,3,0),"") | K8: =IFERROR(VLOOKUP(J8,'BASE DE CLIENTES'!$A:$C,3,0),"") | O8: =IFERROR(VLOOKUP(N8,'BASE DE CLIENTES'!$A:$C,3,0),"") | S8: =IFERROR(VLOOKUP(R8,'BASE DE CLIENTES'!$A:$C,3,0),"") | W8: =IFERROR(VLOOKUP(V8,'BASE DE CLIENTES'!$A:$C,3,0),"")
C9: =IFERROR(VLOOKUP(B9,'BASE DE CLIENTES'!$A:$C,3,0),"") | G9: =IFERROR(VLOOKUP(F9,'BASE DE CLIENTES'!$A:$C,3,0),"") | K9: =IFERROR(VLOOKUP(J9,'BASE DE CLIENTES'!$A:$C,3,0),"") | O9: =IFERROR(VLOOKUP(N9,'BASE DE CLIENTES'!$A:$C,3,0),"") | S9: =IFERROR(VLOOKUP(R9,'BASE DE CLIENTES'!$A:$C,3,0),"") | W9: =IFERROR(VLOOKUP(V9,'BASE DE CLIENTES'!$A:$C,3,0),"")
C10: =IFERROR(VLOOKUP(B10,'BASE DE CLIENTES'!$A:$C,3,0),"") | G10: =IFERROR(VLOOKUP(F10,'BASE DE CLIENTES'!$A:$C,3,0),"") | K10: =IFERROR(VLOOKUP(J10,'BASE DE CLIENTES'!$A:$C,3,0),"") | O10: =IFERROR(VLOOKUP(N10,'BASE DE CLIENTES'!$A:$C,3,0),"") | S10: =IFERROR(VLOOKUP(R10,'BASE DE CLIENTES'!$A:$C,3,0),"") | W10: =IFERROR(VLOOKUP(V10,'BASE DE CLIENTES'!$A:$C,3,0),"")
C11: =IFERROR(VLOOKUP(B11,'BASE DE CLIENTES'!$A:$C,3,0),"") | G11: =IFERROR(VLOOKUP(F11,'BASE DE CLIENTES'!$A:$C,3,0),"") | K11: =IFERROR(VLOOKUP(J11,'BASE DE CLIENTES'!$A:$C,3,0),"") | O11: =IFERROR(VLOOKUP(N11,'BASE DE CLIENTES'!$A:$C,3,0),"") | S11: =IFERROR(VLOOKUP(R11,'BASE DE CLIENTES'!$A:$C,3,0),"") | W11: =IFERROR(VLOOKUP(V11,'BASE DE CLIENTES'!$A:$C,3,0),"")
C12: =IFERROR(VLOOKUP(B12,'BASE DE CLIENTES'!$A:$C,3,0),"") | G12: =IFERROR(VLOOKUP(F12,'BASE DE CLIENTES'!$A:$C,3,0),"") | K12: =IFERROR(VLOOKUP(J12,'BASE DE CLIENTES'!$A:$C,3,0),"") | O12: =IFERROR(VLOOKUP(N12,'BASE DE CLIENTES'!$A:$C,3,0),"") | S12: =IFERROR(VLOOKUP(R12,'BASE DE CLIENTES'!$A:$C,3,0),"") | W12: =IFERROR(VLOOKUP(V12,'BASE DE CLIENTES'!$A:$C,3,0),"")
C13: =IFERROR(VLOOKUP(B13,'BASE DE CLIENTES'!$A:$C,3,0),"") | G13: =IFERROR(VLOOKUP(F13,'BASE DE CLIENTES'!$A:$C,3,0),"") | K13: =IFERROR(VLOOKUP(J13,'BASE DE CLIENTES'!$A:$C,3,0),"") | O13: =IFERROR(VLOOKUP(N13,'BASE DE CLIENTES'!$A:$C,3,0),"") | S13: =IFERROR(VLOOKUP(R13,'BASE DE CLIENTES'!$A:$C,3,0),"") | W13: =IFERROR(VLOOKUP(V13,'BASE DE CLIENTES'!$A:$C,3,0),"")
C14: =IFERROR(VLOOKUP(B14,'BASE DE CLIENTES'!$A:$C,3,0),"") | G14: =IFERROR(VLOOKUP(F14,'BASE DE CLIENTES'!$A:$C,3,0),"") | K14: =IFERROR(VLOOKUP(J14,'BASE DE CLIENTES'!$A:$C,3,0),"") | O14: =IFERROR(VLOOKUP(N14,'BASE DE CLIENTES'!$A:$C,3,0),"") | S14: =IFERROR(VLOOKUP(R14,'BASE DE CLIENTES'!$A:$C,3,0),"") | W14: =IFERROR(VLOOKUP(V14,'BASE DE CLIENTES'!$A:$C,3,0),"")
C15: =IFERROR(VLOOKUP(B15,'BASE DE CLIENTES'!$A:$C,3,0),"") | G15: =IFERROR(VLOOKUP(F15,'BASE DE CLIENTES'!$A:$C,3,0),"") | K15: =IFERROR(VLOOKUP(J15,'BASE DE CLIENTES'!$A:$C,3,0),"") | O15: =IFERROR(VLOOKUP(N15,'BASE DE CLIENTES'!$A:$C,3,0),"") | S15: =IFERROR(VLOOKUP(R15,'BASE DE CLIENTES'!$A:$C,3,0),"") | W15: =IFERROR(VLOOKUP(V15,'BASE DE CLIENTES'!$A:$C,3,0),"")
... C100: =IFERROR(VLOOKUP(B100,'BASE DE CLIENTES'!$A:$C,3,0),"") | G100: =IFERROR(VLOOKUP(F100,'BASE DE CLIENTES'!$A:$C,3,0),"") | K100: =IFERROR(VLOOKUP(J100,'BASE DE CLIENTES'!$A:$C,3,0),"") | O100: =IFERROR(VLOOKUP(N100,'BASE DE CLIENTES'!$A:$C,3,0),"") | S100: =IFERROR(VLOOKUP(R100,'BASE DE CLIENTES'!$A:$C,3,0),"") | W100: =IFERROR(VLOOKUP(V100,'BASE DE CLIENTES'!$A:$C,3,0),"")

Sheet GABRIEL SANTOS NEVES
B2: SEG | F2: TER | J2: QUA | N2: QUI | R2: SEX | V2: SÁB
B3: COD. | C3: CLIENTE | D3: EQUIPAMENTO | E3: ATIVIDADE | F3: COD. | G3: CLIENTE | H3: EQUIPAMENTO | I3: ATIVIDADE | J3: COD. | K3: CLIENTE | L3: EQUIPAMENTO | M3: ATIVIDADE | N3: COD. | O3: CLIENTE | P3: EQUIPAMENTO | Q3: ATIVIDADE | R3: COD. | S3: CLIENTE | T3: EQUIPAMENTO | U3: ATIVIDADE | V3: COD. | W3: CLIENTE | X3: EQUIPAMENTO | Y3: ATIVIDADE
C4: =IFERROR(VLOOKUP(B4,'BASE DE CLIENTES'!$A:$C,3,0),"") | G4: =IFERROR(VLOOKUP(F4,'BASE DE CLIENTES'!$A:$C,3,0),"") | K4: =IFERROR(VLOOKUP(J4,'BASE DE CLIENTES'!$A:$C,3,0),"") | O4: =IFERROR(VLOOKUP(N4,'BASE DE CLIENTES'!$A:$C,3,0),"") | S4: =IFERROR(VLOOKUP(R4,'BASE DE CLIENTES'!$A:$C,3,0),"") | W4: =IFERROR(VLOOKUP(V4,'BASE DE CLIENTES'!$A:$C,3,0),"")
C5: =IFERROR(VLOOKUP(B5,'BASE DE CLIENTES'!$A:$C,3,0),"") | G5: =IFERROR(VLOOKUP(F5,'BASE DE CLIENTES'!$A:$C,3,0),"") | K5: =IFERROR(VLOOKUP(J5,'BASE DE CLIENTES'!$A:$C,3,0),"") | O5: =IFERROR(VLOOKUP(N5,'BASE DE CLIENTES'!$A:$C,3,0),"") | S5: =IFERROR(VLOOKUP(R5,'BASE DE CLIENTES'!$A:$C,3,0),"") | W5: =IFERROR(VLOOKUP(V5,'BASE DE CLIENTES'!$A:$C,3,0),"")
C6: =IFERROR(VLOOKUP(B6,'BASE DE CLIENTES'!$A:$C,3,0),"") | G6: =IFERROR(VLOOKUP(F6,'BASE DE CLIENTES'!$A:$C,3,0),"") | K6: =IFERROR(VLOOKUP(J6,'BASE DE CLIENTES'!$A:$C,3,0),"") | O6: =IFERROR(VLOOKUP(N6,'BASE DE CLIENTES'!$A:$C,3,0),"") | S6: =IFERROR(VLOOKUP(R6,'BASE DE CLIENTES'!$A:$C,3,0),"") | W6: =IFERROR(VLOOKUP(V6,'BASE DE CLIENTES'!$A:$C,3,0),"")
C7: =IFERROR(VLOOKUP(B7,'BASE DE CLIENTES'!$A:$C,3,0),"") | G7: =IFERROR(VLOOKUP(F7,'BASE DE CLIENTES'!$A:$C,3,0),"") | K7: =IFERROR(VLOOKUP(J7,'BASE DE CLIENTES'!$A:$C,3,0),"") | O7: =IFERROR(VLOOKUP(N7,'BASE DE CLIENTES'!$A:$C,3,0),"") | S7: =IFERROR(VLOOKUP(R7,'BASE DE CLIENTES'!$A:$C,3,0),"") | W7: =IFERROR(VLOOKUP(V7,'BASE DE CLIENTES'!$A:$C,3,0),"")
C8: =IFERROR(VLOOKUP(B8,'BASE DE CLIENTES'!$A:$C,3,0),"") | G8: =IFERROR(VLOOKUP(F8,'BASE DE CLIENTES'!$A:$C,3,0),"") | K8: =IFERROR(VLOOKUP(J8,'BASE DE CLIENTES'!$A:$C,3,0),"") | O8: =IFERROR(VLOOKUP(N8,'BASE DE CLIENTES'!$A:$C,3,0),"") | S8: =IFERROR(VLOOKUP(R8,'BASE DE CLIENTES'!$A:$C,3,0),"") | W8: =IFERROR(VLOOKUP(V8,'BASE DE CLIENTES'!$A:$C,3,0),"")
C9: =IFERROR(VLOOKUP(B9,'BASE DE CLIENTES'!$A:$C,3,0),"") | G9: =IFERROR(VLOOKUP(F9,'BASE DE CLIENTES'!$A:$C,3,0),"") | K9: =IFERROR(VLOOKUP(J9,'BASE DE CLIENTES'!$A:$C,3,0),"") | O9: =IFERROR(VLOOKUP(N9,'BASE DE CLIENTES'!$A:$C,3,0),"") | S9: =IFERROR(VLOOKUP(R9,'BASE DE CLIENTES'!$A:$C,3,0),"") | W9: =IFERROR(VLOOKUP(V9,'BASE DE CLIENTES'!$A:$C,3,0),"")
